Workbook

Sheet Resumen v2
J3: Fecha | K3: Semana del año
J4: =+TODAY() -> 46308 | K4: =+WEEKNUM(J4) -> 42 | X4: A | Y4: B | AD4: Ifs
X5: 1.5 | Y5: 1.5 | AD5: Si a o b es menor o igual a 0, entonces 0 | AG5: =+IF(AA7<0,0,1) -> 1 | AH5: =+IF(AB7<0,0,1) -> 1
H6: Codigo | I6: Mes | J6: Semana (etiqueta) | K6: Semana | L6: Tipo de Semana | M6: NOMBRE | N6: Horas Efectivas | O6: Ordinarias Semana Completa | P6: Ordinarias Semana Dividida | Q6: Ordinarias Total | R6: Excedente/Faltante | S6: Sistema | T6: Proporción Dia | U6: Proporción Noche | V6: Saldo Horas Dia | W6: Saldo Horas Noche | X6: Multiplicador día (1.5) | Y6: Multiplicador Noche (2) | AD6: Si a es mayor a cero y b es menor a cero, sacar suma, si la suma es menor a 0, entonces 0 | AG6: =+IF(AA7+AB7<0,0,AA7+AB7) -> 67.125
H7: =+I7&J7&K7&M7 -> SEPTIEMBRESem3838GUZMÁN MORALES EDGAR RICARDO | I7: =+_xlfn.XLOOKUP(K7,DetalleCalculos!W:W,DetalleCalculos!S:S,"",0,1) -> SEPTIEMBRE | J7: =+"Sem"&K7 -> Sem38 | K7: =+$H$17 -> 38 | L7: =+IF(_xlfn.XLOOKUP(K7,DetalleCalculos!W:W,DetalleCalculos!U:U,0,0,1)=7,1,2) -> 1 | M7: GUZMÁN MORALES EDGAR RICARDO | N7: =SUMIFS(DetalleCalculos!$N:$N,DetalleCalculos!$W:$W,$K7,DetalleCalculos!$H:$H,$M7)*24 -> 49 | O7: =SUMIFS(DetalleCalculos!$P:$P,DetalleCalculos!$W:$W,$K7,DetalleCalculos!$H:$H,$M7) -> 44 | P7: =SUMIFS(DetalleCalculos!$Q:$Q,DetalleCalculos!$W:$W,$K7,DetalleCalculos!$H:$H,$M7) -> 0 | Q7: =+IF(L7=1,O7,P7) -> 44 | R7: =+IF(N7-Q7<=0,0,N7-Q7) -> 5 | S7: =_xlfn.XLOOKUP($J7&$K7&$M7,DetalleCalculos!$B:$B,DetalleCalculos!$O:$O,"",0,1) -> 5-0-2 | T7: =+_xlfn.XLOOKUP($S7,'Horarios y Sistemas'!$C:$C,'Horarios y Sistemas'!M:M,0,0,1) -> 1 | U7: =1-T7 -> 0 | V7: =+T7*R7 -> 5 | W7: =+U7*R7 -> 0 | X7: =+V7*X$5 -> 7.5 | Y7: =+W7*Y$5 -> 0 | Z7: Neto Periodo | AA7: =+SUM(X7:X9) -> 36.75 | AB7: =+SUM(Y7:Y9) -> 30.375
H8: =+I8&J8&K8&M8 -> SEPTIEMBRESem3939GUZMÁN MORALES EDGAR RICARDO | I8: =+_xlfn.XLOOKUP(K8,DetalleCalculos!W:W,DetalleCalculos!S:S,"",0,1) -> SEPTIEMBRE | J8: =+"Sem"&K8 -> Sem39 | K8: =+$H$18 -> 39 | L8: =+IF(_xlfn.XLOOKUP(K8,DetalleCalculos!W:W,DetalleCalculos!U:U,0,0,1)=7,1,2) -> 1 | M8: =$M$7 -> GUZMÁN MORALES EDGAR RICARDO | N8: =SUMIFS(DetalleCalculos!$N:$N,DetalleCalculos!$W:$W,$K8,DetalleCalculos!$H:$H,$M8)*24 -> 56.25 | O8: =SUMIFS(DetalleCalculos!$P:$P,DetalleCalculos!$W:$W,$K8,DetalleCalculos!$H:$H,$M8) -> 36 | P8: =SUMIFS(DetalleCalculos!$Q:$Q,DetalleCalculos!$W:$W,$K8,DetalleCalculos!$H:$H,$M8) -> 0 | Q8: =+IF(L8=1,O8,P8) -> 36 | R8: =+IF(N8-Q8<=0,0,N8-Q8) -> 20.25 | S8: =_xlfn.XLOOKUP($J8&$K8&$M8,DetalleCalculos!$B:$B,DetalleCalculos!$O:$O,"",0,1) -> 0-5-2 | T8: =+_xlfn.XLOOKUP($S8,'Horarios y Sistemas'!$C:$C,'Horarios y Sistemas'!M:M,0,0,1) -> 0 | U8: =1-T8 -> 1 | V8: =+T8*R8 -> 0 | W8: =+U8*R8 -> 20.25 | X8: =+V8*X$5 -> 0 | Y8: =+W8*Y$5 -> 30.375 | Z8: Neto Periodo Proporcional | AA8: =+IF(AA7<=0,0,IF(AND(AA7>AB7,AB7<=0),IF(AA7+AB7>0,AA7+AB7,0),IF(AND(AA7>0,AB7>0),AA7,0))) -> 36.75 | AB8: =+IF(AB7<=0,0,IF(AND(AB7>AA7,AA7<=0),IF(AB7+AA7>0,AB7+AA7,0),IF(AND(AB7>0,AA7>0),AB7,0))) -> 30.375 | AC8: Horas Extras Finales | AD8: =+AA8/$X$5 -> 24.5 | AE8: =+AB8/$Y$5 -> 20.25
H9: =+I9&J9&K9&M9 -> SEPTIEMBRESem4040GUZMÁN MORALES EDGAR RICARDO | I9: =+_xlfn.XLOOKUP(K9,DetalleCalculos!W:W,DetalleCalculos!S:S,"",0,1) -> SEPTIEMBRE | J9: =+"Sem"&K9 -> Sem40 | K9: =+$H$19 -> 40 | L9: =+IF(_xlfn.XLOOKUP(K9,DetalleCalculos!W:W,DetalleCalculos!U:U,0,0,1)=7,1,2) -> 1 | M9: =$M$7 -> GUZMÁN MORALES EDGAR RICARDO | N9: =SUMIFS(DetalleCalculos!$N:$N,DetalleCalculos!$W:$W,$K9,DetalleCalculos!$H:$H,$M9)*24 -> 63.5 | O9: =SUMIFS(DetalleCalculos!$P:$P,DetalleCalculos!$W:$W,$K9,DetalleCalculos!$H:$H,$M9) -> 44 | P9: =SUMIFS(DetalleCalculos!$Q:$Q,DetalleCalculos!$W:$W,$K9,DetalleCalculos!$H:$H,$M9) -> 0 | Q9: =+IF(L9=1,O9,P9) -> 44 | R9: =+IF(N9-Q9<=0,0,N9-Q9) -> 19.5 | S9: =_xlfn.XLOOKUP($J9&$K9&$M9,DetalleCalculos!$B:$B,DetalleCalculos!$O:$O,"",0,1) -> 6-0-1 | T9: =+_xlfn.XLOOKUP($S9,'Horarios y Sistemas'!$C:$C,'Horarios y Sistemas'!M:M,0,0,1) -> 1 | U9: =1-T9 -> 0 | V9: =+T9*R9 -> 19.5 | W9: =+U9*R9 -> 0 | X9: =+V9*X$5 -> 29.25 | Y9: =+W9*Y$5 -> 0
N10: =+SUM(N7:N9) -> 168.75 | Q10: =+SUM(Q7:Q9) -> 124 | R10: =+N10-Q10 -> 44.75
Q15: =4*9.5 -> 38
G16: Semanas del periodo (ISO)
G17: Semana 1 | H17: 38
G18: Semana 2 | H18: 39
G19: Semana 3 | H19: 40
B20: Horas Extras Finales
B21: TOTAL (COMO NÚMERO NO HORA) | C21: =+SUM(C23:C89) -> 781.25861 | D21: =+SUM(D23:D89) -> 688.52472 | E21: =+SUM(C21:D21) -> 1469.7833 | F21: =+IF(E21-AE22=0,"SI","NO") -> SI | AC21: Dia | AD21: Noche | AE21: Total
B22: EMPLEADO | C22: Dia | D22: Noche | E22: Total 3 Semanas | H22: Codigo | I22: Mes | J22: Semana (etiqueta) | K22: Semana | L22: Tipo de Semana | M22: NOMBRE | N22: Horas Efectivas | O22: Ordinarias Semana Completa | P22: Ordinarias Semana Dividida | Q22: Ordinarias Total | R22: Excedente/Faltante | S22: Sistema | T22: Proporción Dia | U22: Proporción Noche | V22: Saldo Horas Dia | W22: Saldo Horas Noche | X22: Multiplicador día (1.5) | Y22: Multiplicador Noche (2) | AC22: =+SUMIF($AC$23:$AC$223,$AC$24,AD23:AD223) -> 781.25861 | AD22: =+SUMIF($AC$23:$AC$223,$AC$24,AE23:AE223) -> 688.52472 | AE22: =+AC22+AD22 -> 1469.7833
B23: ADOLFO DE JESUS LOPEZ CHAVEZ | C23: =+SUMIFS(AD$23:AD$223,$M$23:$M$223,$B23,$AC$23:$AC$223,$B$20) -> 24.5 | D23: =+SUMIFS(AE$23:AE$223,$M$23:$M$223,$B23,$AC$23:$AC$223,$B$20) -> 20.25 | E23: =+SUM(C23:D23) -> 44.75 | H23: =+I23&J23&K23&M23 -> SEPTIEMBRESem3838ADOLFO DE JESUS LOPEZ CHAVEZ | I23: =+_xlfn.XLOOKUP(K23,DetalleCalculos!W:W,DetalleCalculos!S:S,"",0,1) -> SEPTIEMBRE | J23: =+"Sem"&K23 -> Sem38 | K23: =+$H$17 -> 38 | L23: =+IF(_xlfn.XLOOKUP(K23,DetalleCalculos!W:W,DetalleCalculos!U:U,0,0,1)=7,1,2) -> 1 | M23: {=+INDEX($B$23:$B$89,ROUNDUP((ROW()-22)/3,0))} -> ADOLFO DE JESUS LOPEZ CHAVEZ | N23: =SUMIFS(DetalleCalculos!$N:$N,DetalleCalculos!$W:$W,$K23,DetalleCalculos!$H:$H,$M23)*24 -> 49 | O23: =SUMIFS(DetalleCalculos!$P:$P,DetalleCalculos!$W:$W,$K23,DetalleCalculos!$H:$H,$M23) -> 44 | P23: =SUMIFS(DetalleCalculos!$Q:$Q,DetalleCalculos!$W:$W,$K23,DetalleCalculos!$H:$H,$M23) -> 0 | Q23: =+IF(L23=1,O23,P23) -> 44 | R23: =+IF(N23-Q23<=0,0,N23-Q23) -> 5 | S23: =_xlfn.XLOOKUP($J23&$K23&$M23,DetalleCalculos!$B:$B,DetalleCalculos!$O:$O,"",0,1) -> 5-0-2 | T23: =+_xlfn.XLOOKUP($S23,'Horarios y Sistemas'!$C:$C,'Horarios y Sistemas'!M:M,0,0,1) -> 1 | U23: =1-T23 -> 0 | V23: =+T23*R23 -> 5 | W23: =+U23*R23 -> 0 | X23: =+V23*X$5 -> 7.5 | Y23: =+W23*Y$5 -> 0 | Z23: Neto Periodo | AA23: =+SUM(X23:X25) -> 36.75 | AB23: =+SUM(Y23:Y25) -> 30.375
B24: AMILCAR EDELBERTO LOPEZ AROCHE | C24: =+SUMIFS(AD$23:AD$223,$M$23:$M$223,$B24,$AC$23:$AC$223,$B$20) -> 18.75 | D24: =+SUMIFS(AE$23:AE$223,$M$23:$M$223,$B24,$AC$23:$AC$223,$B$20) -> 21.25 | E24: =+SUM(C24:D24) -> 40 | H24: =+I24&J24&K24&M24 -> SEPTIEMBRESem3939ADOLFO DE JESUS LOPEZ CHAVEZ | I24: =+_xlfn.XLOOKUP(K24,DetalleCalculos!W:W,DetalleCalculos!S:S,"",0,1) -> SEPTIEMBRE | J24: =+"Sem"&K24 -> Sem39 | K24: =+$H$18 -> 39 | L24: =+IF(_xlfn.XLOOKUP(K24,DetalleCalculos!W:W,DetalleCalculos!U:U,0,0,1)=7,1,2) -> 1 | M24: {=+INDEX($B$23:$B$89,ROUNDUP((ROW()-22)/3,0))} -> ADOLFO DE JESUS LOPEZ CHAVEZ | N24: =SUMIFS(DetalleCalculos!$N:$N,DetalleCalculos!$W:$W,$K24,DetalleCalculos!$H:$H,$M24)*24 -> 56.25 | O24: =SUMIFS(DetalleCalculos!$P:$P,DetalleCalculos!$W:$W,$K24,DetalleCalculos!$H:$H,$M24) -> 36 | P24: =SUMIFS(DetalleCalculos!$Q:$Q,DetalleCalculos!$W:$W,$K24,DetalleCalculos!$H:$H,$M24) -> 0 | Q24: =+IF(L24=1,O24,P24) -> 36 | R24: =+IF(N24-Q24<=0,0,N24-Q24) -> 20.25 | S24: =_xlfn.XLOOKUP($J24&$K24&$M24,DetalleCalculos!$B:$B,DetalleCalculos!$O:$O,"",0,1) -> 0-5-2 | T24: =+_xlfn.XLOOKUP($S24,'Horarios y Sistemas'!$C:$C,'Horarios y Sistemas'!M:M,0,0,1) -> 0 | U24: =1-T24 -> 1 | V24: =+T24*R24 -> 0 | W24: =+U24*R24 -> 20.25 | X24: =+V24*X$5 -> 0 | Y24: =+W24*Y$5 -> 30.375 | Z24: Neto Periodo Proporcional | AA24: =+IF(AA23<=0,0,IF(AND(AA23>AB23,AB23<=0),IF(AA23+AB23>0,AA23+AB23,0),IF(AND(AA23>0,AB23>0),AA23,0))) -> 36.75 | AB24: =+IF(AB23<=0,0,IF(AND(AB23>AA23,AA23<=0),IF(AB23+AA23>0,AB23+AA23,0),IF(AND(AB23>0,AA23>0),AB23,0))) -> 30.375 | AC24: Horas Extras Finales | AD24: =+AA24/$X$5 -> 24.5 | AE24: =+AB24/$Y$5 -> 20.25
B25: BAYRON AMILCAR JIMENEZ VEGA | C25: =+SUMIFS(AD$23:AD$223,$M$23:$M$223,$B25,$AC$23:$AC$223,$B$20) -> 0 | D25: =+SUMIFS(AE$23:AE$223,$M$23:$M$223,$B25,$AC$23:$AC$223,$B$20) -> 9 | E25: =+SUM(C25:D25) -> 9 | H25: =+I25&J25&K25&M25 -> SEPTIEMBRESem4040ADOLFO DE JESUS LOPEZ CHAVEZ | I25: =+_xlfn.XLOOKUP(K25,DetalleCalculos!W:W,DetalleCalculos!S:S,"",0,1) -> SEPTIEMBRE | J25: =+"Sem"&K25 -> Sem40 | K25: =+$H$19 -> 40 | L25: =+IF(_xlfn.XLOOKUP(K25,DetalleCalculos!W:W,DetalleCalculos!U:U,0,0,1)=7,1,2) -> 1 | M25: {=+INDEX($B$23:$B$89,ROUNDUP((ROW()-22)/3,0))} -> ADOLFO DE JESUS LOPEZ CHAVEZ | N25: =SUMIFS(DetalleCalculos!$N:$N,DetalleCalculos!$W:$W,$K25,DetalleCalculos!$H:$H,$M25)*24 -> 63.5 | O25: =SUMIFS(DetalleCalculos!$P:$P,DetalleCalculos!$W:$W,$K25,DetalleCalculos!$H:$H,$M25) -> 44 | P25: =SUMIFS(DetalleCalculos!$Q:$Q,DetalleCalculos!$W:$W,$K25,DetalleCalculos!$H:$H,$M25) -> 0 | Q25: =+IF(L25=1,O25,P25) -> 44 | R25: =+IF(N25-Q25<=0,0,N25-Q25) -> 19.5 | S25: =_xlfn.XLOOKUP($J25&$K25&$M25,DetalleCalculos!$B:$B,DetalleCalculos!$O:$O,"",0,1) -> 6-0-1 | T25: =+_xlfn.XLOOKUP($S25,'Horarios y Sistemas'!$C:$C,'Horarios y Sistemas'!M:M,0,0,1) -> 1 | U25: =1-T25 -> 0 | V25: =+T25*R25 -> 19.5 | W25: =+U25*R25 -> 0 | X25: =+V25*X$5 -> 29.25 | Y25: =+W25*Y$5 -> 0
B26: BRYAN GEOVANI PELEN MAYEN | C26: =+SUMIFS(AD$23:AD$223,$M$23:$M$223,$B26,$AC$23:$AC$223,$B$20) -> 18.75 | D26: =+SUMIFS(AE$23:AE$223,$M$23:$M$223,$B26,$AC$23:$AC$223,$B$20) -> 21.25 | E26: =+SUM(C26:D26) -> 40 | H26: =+I26&J26&K26&M26 -> SEPTIEMBRESem3838AMILCAR EDELBERTO LOPEZ AROCHE | I26: =+_xlfn.XLOOKUP(K26,DetalleCalculos!W:W,DetalleCalculos!S:S,"",0,1) -> SEPTIEMBRE | J26: =+"Sem"&K26 -> Sem38 | K26: =+$H$17 -> 38 | L26: =+IF(_xlfn.XLOOKUP(K26,DetalleCalculos!W:W,DetalleCalculos!U:U,0,0,1)=7,1,2) -> 1 | M26: {=+INDEX($B$23:$B$89,ROUNDUP((ROW()-22)/3,0))} -> AMILCAR EDELBERTO LOPEZ AROCHE | N26: =SUMIFS(DetalleCalculos!$N:$N,DetalleCalculos!$W:$W,$K26,DetalleCalculos!$H:$H,$M26)*24 -> 41 | O26: =SUMIFS(DetalleCalculos!$P:$P,DetalleCalculos!$W:$W,$K26,DetalleCalculos!$H:$H,$M26) -> 38 | P26: =SUMIFS(DetalleCalculos!$Q:$Q,DetalleCalculos!$W:$W,$K26,DetalleCalculos!$H:$H,$M26) -> 0 | Q26: =+IF(L26=1,O26,P26) -> 38 | R26: =+IF(N26-Q26<=0,0,N26-Q26) -> 3 | S26: =_xlfn.XLOOKUP($J26&$K26&$M26,DetalleCalculos!$B:$B,DetalleCalculos!$O:$O,"",0,1) -> 1-3-3 | T26: =+_xlfn.XLOOKUP($S26,'Horarios y Sistemas'!$C:$C,'Horarios y Sistemas'!M:M,0,0,1) -> 0.25 | U26: =1-T26 -> 0.75 | V26: =+T26*R26 -> 0.75 | W26: =+U26*R26 -> 2.25 | X26: =+V26*X$5 -> 1.125 | Y26: =+W26*Y$5 -> 3.375 | Z26: Neto Periodo | AA26: =+SUM(X26:X28) -> 28.125 | AB26: =+SUM(Y26:Y28) -> 31.875
B27: Braulio Vinicio López Rancho | C27: =+SUMIFS(AD$23:AD$223,$M$23:$M$223,$B27,$AC$23:$AC$223,$B$20) -> 30 | D27: =+SUMIFS(AE$23:AE$223,$M$23:$M$223,$B27,$AC$23:$AC$223,$B$20) -> 0 | E27: =+SUM(C27:D27) -> 30 | H27: =+I27&J27&K27&M27 -> SEPTIEMBRESem3939AMILCAR EDELBERTO LOPEZ AROCHE | I27: =+_xlfn.XLOOKUP(K27,DetalleCalculos!W:W,DetalleCalculos!S:S,"",0,1) -> SEPTIEMBRE | J27: =+"Sem"&K27 -> Sem39 | K27: =+$H$18 -> 39 | L27: =+IF(_xlfn.XLOOKUP(K27,DetalleCalculos!W:W,DetalleCalculos!U:U,0,0,1)=7,1,2) -> 1 | M27: {=+INDEX($B$23:$B$89,ROUNDUP((ROW()-22)/3,0))} -> AMILCAR EDELBERTO LOPEZ AROCHE | N27: =SUMIFS(DetalleCalculos!$N:$N,DetalleCalculos!$W:$W,$K27,DetalleCalculos!$H:$H,$M27)*24 -> 62 | O27: =SUMIFS(DetalleCalculos!$P:$P,DetalleCalculos!$W:$W,$K27,DetalleCalculos!$H:$H,$M27) -> 44 | P27: =SUMIFS(DetalleCalculos!$Q:$Q,DetalleCalculos!$W:$W,$K27,DetalleCalculos!$H:$H,$M27) -> 0 | Q27: =+IF(L27=1,O27,P27) -> 44 | R27: =+IF(N27-Q27<=0,0,N27-Q27) -> 18 | S27: =_xlfn.XLOOKUP($J27&$K27&$M27,DetalleCalculos!$B:$B,DetalleCalculos!$O:$O,"",0,1) -> 6-0-1 | T27: =+_xlfn.XLOOKUP($S27,'Horarios y Sistemas'!$C:$C,'Horarios y Sistemas'!M:M,0,0,1) -> 1 | U27: =1-T27 -> 0 | V27: =+T27*R27 -> 18 | W27: =+U27*R27 -> 0 | X27: =+V27*X$5 -> 27 | Y27: =+W27*Y$5 -> 0 | Z27: Neto Periodo Proporcional | AA27: =+IF(AA26<=0,0,IF(AND(AA26>AB26,AB26<=0),IF(AA26+AB26>0,AA26+AB26,0),IF(AND(AA26>0,AB26>0),AA26,0))) -> 28.125 | AB27: =+IF(AB26<=0,0,IF(AND(AB26>AA26,AA26<=0),IF(AB26+AA26>0,AB26+AA26,0),IF(AND(AB26>0,AA26>0),AB26,0))) -> 31.875 | AC27: Horas Extras Finales | AD27: =+AA27/$X$5 -> 18.75 | AE27: =+AB27/$Y$5 -> 21.25
B28: Bryan Amilcar Yax Rivera | C28: =+SUMIFS(AD$23:AD$223,$M$23:$M$223,$B28,$AC$23:$AC$223,$B$20) -> 24.88 | D28: =+SUMIFS(AE$23:AE$223,$M$23:$M$223,$B28,$AC$23:$AC$223,$B$20) -> 31.52 | E28: =+SUM(C28:D28) -> 56.4 | H28: =+I28&J28&K28&M28 -> SEPTIEMBRESem4040AMILCAR EDELBERTO LOPEZ AROCHE | I28: =+_xlfn.XLOOKUP(K28,DetalleCalculos!W:W,DetalleCalculos!S:S,"",0,1) -> SEPTIEMBRE | J28: =+"Sem"&K28 -> Sem40 | K28: =+$H$19 -> 40 | L28: =+IF(_xlfn.XLOOKUP(K28,DetalleCalculos!W:W,DetalleCalculos!U:U,0,0,1)=7,1,2) -> 1 | M28: {=+INDEX($B$23:$B$89,ROUNDUP((ROW()-22)/3,0))} -> AMILCAR EDELBERTO LOPEZ AROCHE | N28: =SUMIFS(DetalleCalculos!$N:$N,DetalleCalculos!$W:$W,$K28,DetalleCalculos!$H:$H,$M28)*24 -> 55 | O28: =SUMIFS(DetalleCalculos!$P:$P,DetalleCalculos!$W:$W,$K28,DetalleCalculos!$H:$H,$M28) -> 36 | P28: =SUMIFS(DetalleCalculos!$Q:$Q,DetalleCalculos!$W:$W,$K28,DetalleCalculos!$H:$H,$M28) -> 0 | Q28: =+IF(L28=1,O28,P28) -> 36 | R28: =+IF(N28-Q28<=0,0,N28-Q28) -> 19 | S28: =_xlfn.XLOOKUP($J28&$K28&$M28,DetalleCalculos!$B:$B,DetalleCalculos!$O:$O,"",0,1) -> 0-5-2 | T28: =+_xlfn.XLOOKUP($S28,'Horarios y Sistemas'!$C:$C,'Horarios y Sistemas'!M:M,0,0,1) -> 0 | U28: =1-T28 -> 1 | V28: =+T28*R28 -> 0 | W28: =+U28*R28 -> 19 | X28: =+V28*X$5 -> 0 | Y28: =+W28*Y$5 -> 28.5
B29: CARLOS ANTONIO DE JESUS DUARTE URIAS | C29: =+SUMIFS(AD$23:AD$223,$M$23:$M$223,$B29,$AC$23:$AC$223,$B$20) -> 0 | D29: =+SUMIFS(AE$23:AE$223,$M$23:$M$223,$B29,$AC$23:$AC$223,$B$20) -> 0 | E29: =+SUM(C29:D29) -> 0 | H29: =+I29&J29&K29&M29 -> SEPTIEMBRESem3838BAYRON AMILCAR JIMENEZ VEGA | I29: =+_xlfn.XLOOKUP(K29,DetalleCalculos!W:W,DetalleCalculos!S:S,"",0,1) -> SEPTIEMBRE | J29: =+"Sem"&K29 -> Sem38 | K29: =+$H$17 -> 38 | L29: =+IF(_xlfn.XLOOKUP(K29,DetalleCalculos!W:W,DetalleCalculos!U:U,0,0,1)=7,1,2) -> 1 | M29: {=+INDEX($B$23:$B$89,ROUNDUP((ROW()-22)/3,0))} -> BAYRON AMILCAR JIMENEZ VEGA | N29: =SUMIFS(DetalleCalculos!$N:$N,DetalleCalculos!$W:$W,$K29,DetalleCalculos!$H:$H,$M29)*24 -> 36 | O29: =SUMIFS(DetalleCalculos!$P:$P,DetalleCalculos!$W:$W,$K29,DetalleCalculos!$H:$H,$M29) -> 44 | P29: =SUMIFS(DetalleCalculos!$Q:$Q,DetalleCalculos!$W:$W,$K29,DetalleCalculos!$H:$H,$M29) -> 0 | Q29: =+IF(L29=1,O29,P29) -> 44 | R29: =+IF(N29-Q29<=0,0,N29-Q29) -> 0 | S29: =_xlfn.XLOOKUP($J29&$K29&$M29,DetalleCalculos!$B:$B,DetalleCalculos!$O:$O,"",0,1) -> 5-0-2 | T29: =+_xlfn.XLOOKUP($S29,'Horarios y Sistemas'!$C:$C,'Horarios y Sistemas'!M:M,0,0,1) -> 1 | U29: =1-T29 -> 0 | V29: =+T29*R29 -> 0 | W29: =+U29*R29 -> 0 | X29: =+V29*X$5 -> 0 | Y29: =+W29*Y$5 -> 0 | Z29: Neto Periodo | AA29: =+SUM(X29:X31) -> 0 | AB29: =+SUM(Y29:Y31) -> 13.5
B30: CARLOS DANIEL RUIZ SANTOS | C30: =+SUMIFS(AD$23:AD$223,$M$23:$M$223,$B30,$AC$23:$AC$223,$B$20) -> 18 | D30: =+SUMIFS(AE$23:AE$223,$M$23:$M$223,$B30,$AC$23:$AC$223,$B$20) -> 19 | E30: =+SUM(C30:D30) -> 37 | H30: =+I30&J30&K30&M30 -> SEPTIEMBRESem3939BAYRON AMILCAR JIMENEZ VEGA | I30: =+_xlfn.XLOOKUP(K30,DetalleCalculos!W:W,DetalleCalculos!S:S,"",0,1) -> SEPTIEMBRE | J30: =+"Sem"&K30 -> Sem39 | K30: =+$H$18 -> 39 | L30: =+IF(_xlfn.XLOOKUP(K30,DetalleCalculos!W:W,DetalleCalculos!U:U,0,0,1)=7,1,2) -> 1 | M30: {=+INDEX($B$23:$B$89,ROUNDUP((ROW()-22)/3,0))} -> BAYRON AMILCAR JIMENEZ VEGA | N30: =SUMIFS(DetalleCalculos!$N:$N,DetalleCalculos!$W:$W,$K30,DetalleCalculos!$H:$H,$M30)*24 -> 45 | O30: =SUMIFS(DetalleCalculos!$P:$P,DetalleCalculos!$W:$W,$K30,DetalleCalculos!$H:$H,$M30) -> 36 | P30: =SUMIFS(DetalleCalculos!$Q:$Q,DetalleCalculos!$W:$W,$K30,DetalleCalculos!$H:$H,$M30) -> 0 | Q30: =+IF(L30=1,O30,P30) -> 36 | R30: =+IF(N30-Q30<=0,0,N30-Q30) -> 9 | S30: =_xlfn.XLOOKUP($J30&$K30&$M30,DetalleCalculos!$B:$B,DetalleCalculos!$O:$O,"",0,1) -> 0-5-2 | T30: =+_xlfn.XLOOKUP($S30,'Horarios y Sistemas'!$C:$C,'Horarios y Sistemas'!M:M,0,0,1) -> 0 | U30: =1-T30 -> 1 | V30: =+T30*R30 -> 0 | W30: =+U30*R30 -> 9 | X30: =+V30*X$5 -> 0 | Y30: =+W30*Y$5 -> 13.5 | Z30: Neto Periodo Proporcional | AA30: =+IF(AA29<=0,0,IF(AND(AA29>AB29,AB29<=0),IF(AA29+AB29>0,AA29+AB29,0),IF(AND(AA29>0,AB29>0),AA29,0))) -> 0 | AB30: =+IF(AB29<=0,0,IF(AND(AB29>AA29,AA29<=0),IF(AB29+AA29>0,AB29+AA29,0),IF(AND(AB29>0,AA29>0),AB29,0))) -> 13.5 | AC30: Horas Extras Finales | AD30: =+AA30/$X$5 -> 0 | AE30: =+AB30/$Y$5 -> 9
B31: CASTILLO SOLARES CARLOS ARTURO | C31: =+SUMIFS(AD$23:AD$223,$M$23:$M$223,$B31,$AC$23:$AC$223,$B$20) -> 0 | D31: =+SUMIFS(AE$23:AE$223,$M$23:$M$223,$B31,$AC$23:$AC$223,$B$20) -> 9 | E31: =+SUM(C31:D31) -> 9 | H31: =+I31&J31&K31&M31 -> SEPTIEMBRESem4040BAYRON AMILCAR JIMENEZ VEGA | I31: =+_xlfn.XLOOKUP(K31,DetalleCalculos!W:W,DetalleCalculos!S:S,"",0,1) -> SEPTIEMBRE | J31: =+"Sem"&K31 -> Sem40 | K31: =+$H$19 -> 40 | L31: =+IF(_xlfn.XLOOKUP(K31,DetalleCalculos!W:W,DetalleCalculos!U:U,0,0,1)=7,1,2) -> 1 | M31: {=+INDEX($B$23:$B$89,ROUNDUP((ROW()-22)/3,0))} -> BAYRON AMILCAR JIMENEZ VEGA | N31: =SUMIFS(DetalleCalculos!$N:$N,DetalleCalculos!$W:$W,$K31,DetalleCalculos!$H:$H,$M31)*24 -> 44 | O31: =SUMIFS(DetalleCalculos!$P:$P,DetalleCalculos!$W:$W,$K31,DetalleCalculos!$H:$H,$M31) -> 44 | P31: =SUMIFS(DetalleCalculos!$Q:$Q,DetalleCalculos!$W:$W,$K31,DetalleCalculos!$H:$H,$M31) -> 0 | Q31: =+IF(L31=1,O31,P31) -> 44 | R31: =+IF(N31-Q31<=0,0,N31-Q31) -> 0 | S31: =_xlfn.XLOOKUP($J31&$K31&$M31,DetalleCalculos!$B:$B,DetalleCalculos!$O:$O,"",0,1) -> 6-0-1 | T31: =+_xlfn.XLOOKUP($S31,'Horarios y Sistemas'!$C:$C,'Horarios y Sistemas'!M:M,0,0,1) -> 1 | U31: =1-T31 -> 0 | V31: =+T31*R31 -> 0 | W31: =+U31*R31 -> 0 | X31: =+V31*X$5 -> 0 | Y31: =+W31*Y$5 -> 0
B32: CRISTIAN DANIEL CANAHUI CASTAÑEDA | C32: =+SUMIFS(AD$23:AD$223,$M$23:$M$223,$B32,$AC$23:$AC$223,$B$20) -> 0 | D32: =+SUMIFS(AE$23:AE$223,$M$23:$M$223,$B32,$AC$23:$AC$223,$B$20) -> 0 | E32: =+SUM(C32:D32) -> 0 | H32: =+I32&J32&K32&M32 -> SEPTIEMBRESem3838BRYAN GEOVANI PELEN MAYEN | I32: =+_xlfn.XLOOKUP(K32,DetalleCalculos!W:W,DetalleCalculos!S:S,"",0,1) -> SEPTIEMBRE | J32: =+"Sem"&K32 -> Sem38 | K32: =+$H$17 -> 38 | L32: =+IF(_xlfn.XLOOKUP(K32,DetalleCalculos!W:W,DetalleCalculos!U:U,0,0,1)=7,1,2) -> 1 | M32: {=+INDEX($B$23:$B$89,ROUNDUP((ROW()-22)/3,0))} -> BRYAN GEOVANI PELEN MAYEN | N32: =SUMIFS(DetalleCalculos!$N:$N,DetalleCalculos!$W:$W,$K32,DetalleCalculos!$H:$H,$M32)*24 -> 41 | O32: =SUMIFS(DetalleCalculos!$P:$P,DetalleCalculos!$W:$W,$K32,DetalleCalculos!$H:$H,$M32) -> 38 | P32: =SUMIFS(DetalleCalculos!$Q:$Q,DetalleCalculos!$W:$W,$K32,DetalleCalculos!$H:$H,$M32) -> 0 | Q32: =+IF(L32=1,O32,P32) -> 38 | R32: =+IF(N32-Q32<=0,0,N32-Q32) -> 3 | S32: =_xlfn.XLOOKUP($J32&$K32&$M32,DetalleCalculos!$B:$B,DetalleCalculos!$O:$O,"",0,1) -> 1-3-3 | T32: =+_xlfn.XLOOKUP($S32,'Horarios y Sistemas'!$C:$C,'Horarios y Sistemas'!M:M,0,0,1) -> 0.25 | U32: =1-T32 -> 0.75 | V32: =+T32*R32 -> 0.75 | W32: =+U32*R32 -> 2.25 | X32: =+V32*X$5 -> 1.125 | Y32: =+W32*Y$5 -> 3.375 | Z32: Neto Periodo | AA32: =+SUM(X32:X34) -> 28.125 | AB32: =+SUM(Y32:Y34) -> 31.875
B33: Carlos Humberto Alvarado | C33: =+SUMIFS(AD$23:AD$223,$M$23:$M$223,$B33,$AC$23:$AC$223,$B$20) -> 26 | D33: =+SUMIFS(AE$23:AE$223,$M$23:$M$223,$B33,$AC$23:$AC$223,$B$20) -> 0 | E33: =+SUM(C33:D33) -> 26 | H33: =+I33&J33&K33&M33 -> SEPTIEMBRESem3939BRYAN GEOVANI PELEN MAYEN | I33: =+_xlfn.XLOOKUP(K33,DetalleCalculos!W:W,DetalleCalculos!S:S,"",0,1) -> SEPTIEMBRE | J33: =+"Sem"&K33 -> Sem39 | K33: =+$H$18 -> 39 | L33: =+IF(_xlfn.XLOOKUP(K33,DetalleCalculos!W:W,DetalleCalculos!U:U,0,0,1)=7,1,2) -> 1 | M33: {=+INDEX($B$23:$B$89,ROUNDUP((ROW()-22)/3,0))} -> BRYAN GEOVANI PELEN MAYEN | N33: =SUMIFS(DetalleCalculos!$N:$N,DetalleCalculos!$W:$W,$K33,DetalleCalculos!$H:$H,$M33)*24 -> 62 | O33: =SUMIFS(DetalleCalculos!$P:$P,DetalleCalculos!$W:$W,$K33,DetalleCalculos!$H:$H,$M33) -> 44 | P33: =SUMIFS(DetalleCalculos!$Q:$Q,DetalleCalculos!$W:$W,$K33,DetalleCalculos!$H:$H,$M33) -> 0 | Q33: =+IF(L33=1,O33,P33) -> 44 | R33: =+IF(N33-Q33<=0,0,N33-Q33) -> 18 | S33: =_xlfn.XLOOKUP($J33&$K33&$M33,DetalleCalculos!$B:$B,DetalleCalculos!$O:$O,"",0,1) -> 6-0-1 | T33: =+_xlfn.XLOOKUP($S33,'Horarios y Sistemas'!$C:$C,'Horarios y Sistemas'!M:M,0,0,1) -> 1 | U33: =1-T33 -> 0 | V33: =+T33*R33 -> 18 | W33: =+U33*R33 -> 0 | X33: =+V33*X$5 -> 27 | Y33: =+W33*Y$5 -> 0 | Z33: Neto Periodo Proporcional | AA33: =+IF(AA32<=0,0,IF(AND(AA32>AB32,AB32<=0),IF(AA32+AB32>0,AA32+AB32,0),IF(AND(AA32>0,AB32>0),AA32,0))) -> 28.125 | AB33: =+IF(AB32<=0,0,IF(AND(AB32>AA32,AA32<=0),IF(AB32+AA32>0,AB32+AA32,0),IF(AND(AB32>0,AA32>0),AB32,0))) -> 31.875 | AC33: Horas Extras Finales | AD33: =+AA33/$X$5 -> 18.75 | AE33: =+AB33/$Y$5 -> 21.25
B34: Christian Omar Tiney Davila | C34: =+SUMIFS(AD$23:AD$223,$M$23:$M$223,$B34,$AC$23:$AC$223,$B$20) -> 26 | D34: =+SUMIFS(AE$23:AE$223,$M$23:$M$223,$B34,$AC$23:$AC$223,$B$20) -> 0 | E34: =+SUM(C34:D34) -> 26 | H34: =+I34&J34&K34&M34 -> SEPTIEMBRESem4040BRYAN GEOVANI PELEN MAYEN | I34: =+_xlfn.XLOOKUP(K34,DetalleCalculos!W:W,DetalleCalculos!S:S,"",0,1) -> SEPTIEMBRE | J34: =+"Sem"&K34 -> Sem40 | K34: =+$H$19 -> 40 | L34: =+IF(_xlfn.XLOOKUP(K34,DetalleCalculos!W:W,DetalleCalculos!U:U,0,0,1)=7,1,2) -> 1 | M34: {=+INDEX($B$23:$B$89,ROUNDUP((ROW()-22)/3,0))} -> BRYAN GEOVANI PELEN MAYEN | N34: =SUMIFS(DetalleCalculos!$N:$N,DetalleCalculos!$W:$W,$K34,DetalleCalculos!$H:$H,$M34)*24 -> 55 | O34: =SUMIFS(DetalleCalculos!$P:$P,DetalleCalculos!$W:$W,$K34,DetalleCalculos!$H:$H,$M34) -> 36 | P34: =SUMIFS(DetalleCalculos!$Q:$Q,DetalleCalculos!$W:$W,$K34,DetalleCalculos!$H:$H,$M34) -> 0 | Q34: =+IF(L34=1,O34,P34) -> 36 | R34: =+IF(N34-Q34<=0,0,N34-Q34) -> 19 | S34: =_xlfn.XLOOKUP($J34&$K34&$M34,DetalleCalculos!$B:$B,DetalleCalculos!$O:$O,"",0,1) -> 0-5-2 | T34: =+_xlfn.XLOOKUP($S34,'Horarios y Sistemas'!$C:$C,'Horarios y Sistemas'!M:M,0,0,1) -> 0 | U34: =1-T34 -> 1 | V34: =+T34*R34 -> 0 | W34: =+U34*R34 -> 19 | X34: =+V34*X$5 -> 0 | Y34: =+W34*Y$5 -> 28.5
B35: DE PAZ REYES VICTOR ALFONSO | C35: =+SUMIFS(AD$23:AD$223,$M$23:$M$223,$B35,$AC$23:$AC$223,$B$20) -> 23.5175 | D35: =+SUMIFS(AE$23:AE$223,$M$23:$M$223,$B35,$AC$23:$AC$223,$B$20) -> 15.1325 | E35: =+SUM(C35:D35) -> 38.65 | H35: =+I35&J35&K35&M35 -> SEPTIEMBRESem3838Braulio Vinicio López Rancho | I35: =+_xlfn.XLOOKUP(K35,DetalleCalculos!W:W,DetalleCalculos!S:S,"",0,1) -> SEPTIEMBRE | J35: =+"Sem"&K35 -> Sem38 | K35: =+$H$17 -> 38 | L35: =+IF(_xlfn.XLOOKUP(K35,DetalleCalculos!W:W,DetalleCalculos!U:U,0,0,1)=7,1,2) -> 1 | M35: {=+INDEX($B$23:$B$89,ROUNDUP((ROW()-22)/3,0))} -> Braulio Vinicio López Rancho | N35: =SUMIFS(DetalleCalculos!$N:$N,DetalleCalculos!$W:$W,$K35,DetalleCalculos!$H:$H,$M35)*24 -> 52 | O35: =SUMIFS(DetalleCalculos!$P:$P,DetalleCalculos!$W:$W,$K35,DetalleCalculos!$H:$H,$M35) -> 44 | P35: =SUMIFS(DetalleCalculos!$Q:$Q,DetalleCalculos!$W:$W,$K35,DetalleCalculos!$H:$H,$M35) -> 0 | Q35: =+IF(L35=1,O35,P35) -> 44 | R35: =+IF(N35-Q35<=0,0,N35-Q35) -> 8 | S35: =_xlfn.XLOOKUP($J35&$K35&$M35,DetalleCalculos!$B:$B,DetalleCalculos!$O:$O,"",0,1) -> 5-0-2 | T35: =+_xlfn.XLOOKUP($S35,'Horarios y Sistemas'!$C:$C,'Horarios y Sistemas'!M:M,0,0,1) -> 1 | U35: =1-T35 -> 0 | V35: =+T35*R35 -> 8 | W35: =+U35*R35 -> 0 | X35: =+V35*X$5 -> 12 | Y35: =+W35*Y$5 -> 0 | Z35: Neto Periodo | AA35: =+SUM(X35:X37) -> 45 | AB35: =+SUM(Y35:Y37) -> 0
B36: David Alexander Ordoñez Sales | C36: =+SUMIFS(AD$23:AD$223,$M$23:$M$223,$B36,$AC$23:$AC$223,$B$20) -> 2.88 | D36: =+SUMIFS(AE$23:AE$223,$M$23:$M$223,$B36,$AC$23:$AC$223,$B$20) -> 30.52 | E36: =+SUM(C36:D36) -> 33.4 | H36: =+I36&J36&K36&M36 -> SEPTIEMBRESem3939Braulio Vinicio López Rancho | I36: =+_xlfn.XLOOKUP(K36,DetalleCalculos!W:W,DetalleCalculos!S:S,"",0,1) -> SEPTIEMBRE | J36: =+"Sem"&K36 -> Sem39 | K36: =+$H$18 -> 39 | L36: =+IF(_xlfn.XLOOKUP(K36,DetalleCalculos!W:W,DetalleCalculos!U:U,0,0,1)=7,1,2) -> 1 | M36: {=+INDEX($B$23:$B$89,ROUNDUP((ROW()-22)/3,0))} -> Braulio Vinicio López Rancho | N36: =SUMIFS(DetalleCalculos!$N:$N,DetalleCalculos!$W:$W,$K36,DetalleCalculos!$H:$H,$M36)*24 -> 33 | O36: =SUMIFS(DetalleCalculos!$P:$P,DetalleCalculos!$W:$W,$K36,DetalleCalculos!$H:$H,$M36) -> 36 | P36: =SUMIFS(DetalleCalculos!$Q:$Q,DetalleCalculos!$W:$W,$K36,DetalleCalculos!$H:$H,$M36) -> 0 | Q36: =+IF(L36=1,O36,P36) -> 36 | R36: =+IF(N36-Q36<=0,0,N36-Q36) -> 0 | S36: =_xlfn.XLOOKUP($J36&$K36&$M36,DetalleCalculos!$B:$B,DetalleCalculos!$O:$O,"",0,1) -> 0-4-3 | T36: =+_xlfn.XLOOKUP($S36,'Horarios y Sistemas'!$C:$C,'Horarios y Sistemas'!M:M,0,0,1) -> 0 | U36: =1-T36 -> 1 | V36: =+T36*R36 -> 0 | W36: =+U36*R36 -> 0 | X36: =+V36*X$5 -> 0 | Y36: =+W36*Y$5 -> 0 | Z36: Neto Periodo Proporcional | AA36: =+IF(AA35<=0,0,IF(AND(AA35>AB35,AB35<=0),IF(AA35+AB35>0,AA35+AB35,0),IF(AND(AA35>0,AB35>0),AA35,0))) -> 45 | AB36: =+IF(AB35<=0,0,IF(AND(AB35>AA35,AA35<=0),IF(AB35+AA35>0,AB35+AA35,0),IF(AND(AB35>0,AA35>0),AB35,0))) -> 0 | AC36: Horas Extras Finales | AD36: =+AA36/$X$5 -> 30 | AE36: =+AB36/$Y$5 -> 0
B37: Diego Flavio Rivas | C37: =+SUMIFS(AD$23:AD$223,$M$23:$M$223,$B37,$AC$23:$AC$223,$B$20) -> 2.88 | D37: =+SUMIFS(AE$23:AE$223,$M$23:$M$223,$B37,$AC$23:$AC$223,$B$20) -> 30.52 | E37: =+SUM(C37:D37) -> 33.4 | H37: =+I37&J37&K37&M37 -> SEPTIEMBRESem4040Braulio Vinicio López Rancho | I37: =+_xlfn.XLOOKUP(K37,DetalleCalculos!W:W,DetalleCalculos!S:S,"",0,1) -> SEPTIEMBRE | J37: =+"Sem"&K37 -> Sem40 | K37: =+$H$19 -> 40 | L37: =+IF(_xlfn.XLOOKUP(K37,DetalleCalculos!W:W,DetalleCalculos!U:U,0,0,1)=7,1,2) -> 1 | M37: {=+INDEX($B$23:$B$89,ROUNDUP((ROW()-22)/3,0))} -> Braulio Vinicio López Rancho | N37: =SUMIFS(DetalleCalculos!$N:$N,DetalleCalculos!$W:$W,$K37,DetalleCalculos!$H:$H,$M37)*24 -> 66 | O37: =SUMIFS(DetalleCalculos!$P:$P,DetalleCalculos!$W:$W,$K37,DetalleCalculos!$H:$H,$M37) -> 44 | P37: =SUMIFS(DetalleCalculos!$Q:$Q,DetalleCalculos!$W:$W,$K37,DetalleCalculos!$H:$H,$M37) -> 0 | Q37: =+IF(L37=1,O37,P37) -> 44 | R37: =+IF(N37-Q37<=0,0,N37-Q37) -> 22 | S37: =_xlfn.XLOOKUP($J37&$K37&$M37,DetalleCalculos!$B:$B,DetalleCalculos!$O:$O,"",0,1) -> 6-0-1 | T37: =+_xlfn.XLOOKUP($S37,'Horarios y Sistemas'!$C:$C,'Horarios y Sistemas'!M:M,0,0,1) -> 1 | U37: =1-T37 -> 0 | V37: =+T37*R37 -> 22 | W37: =+U37*R37 -> 0 | X37: =+V37*X$5 -> 33 | Y37: =+W37*Y$5 -> 0
B38: EDSON JAIR LEAL GRIJALVA | C38: =+SUMIFS(AD$23:AD$223,$M$23:$M$223,$B38,$AC$23:$AC$223,$B$20) -> 0 | D38: =+SUMIFS(AE$23:AE$223,$M$23:$M$223,$B38,$AC$23:$AC$223,$B$20) -> 0 | E38: =+SUM(C38:D38) -> 0 | H38: =+I38&J38&K38&M38 -> SEPTIEMBRESem3838Bryan Amilcar Yax Rivera | I38: =+_xlfn.XLOOKUP(K38,DetalleCalculos!W:W,DetalleCalculos!S:S,"",0,1) -> SEPTIEMBRE | J38: =+"Sem"&K38 -> Sem38 | K38: =+$H$17 -> 38 | L38: =+IF(_xlfn.XLOOKUP(K38,DetalleCalculos!W:W,DetalleCalculos!U:U,0,0,1)=7,1,2) -> 1 | M38: {=+INDEX($B$23:$B$89,ROUNDUP((ROW()-22)/3,0))} -> Bryan Amilcar Yax Rivera | N38: =SUMIFS(DetalleCalculos!$N:$N,DetalleCalculos!$W:$W,$K38,DetalleCalculos!$H:$H,$M38)*24 -> 52 | O38: =SUMIFS(DetalleCalculos!$P:$P,DetalleCalculos!$W:$W,$K38,DetalleCalculos!$H:$H,$M38) -> 37.6 | P38: =SUMIFS(DetalleCalculos!$Q:$Q,DetalleCalculos!$W:$W,$K38,DetalleCalculos!$H:$H,$M38) -> 0 | Q38: =+IF(L38=1,O38,P38) -> 37.6 | R38: =+IF(N38-Q38<=0,0,N38-Q38) -> 14.4 | S38: =_xlfn.XLOOKUP($J38&$K38&$M38,DetalleCalculos!$B:$B,DetalleCalculos!$O:$O,"",0,1) -> 1-4-2 | T38: =+_xlfn.XLOOKUP($S38,'Horarios y Sistemas'!$C:$C,'Horarios y Sistemas'!M:M,0,0,1) -> 0.2 | U38: =1-T38 -> 0.8 | V38: =+T38*R38 -> 2.88 | W38: =+U38*R38 -> 11.52 | X38: =+V38*X$5 -> 4.32 | Y38: =+W38*Y$5 -> 17.28 | Z38: Neto Periodo | AA38: =+SUM(X38:X40) -> 37.32 | AB38: =+SUM(Y38:Y40) -> 47.28
B39: EFREN ESTUARDO LOPEZ GARCIA | C39: =+SUMIFS(AD$23:AD$223,$M$23:$M$223,$B39,$AC$23:$AC$223,$B$20) -> 13.777778 | D39: =+SUMIFS(AE$23:AE$223,$M$23:$M$223,$B39,$AC$23:$AC$223,$B$20) -> 2.5555556 | E39: =+SUM(C39:D39) -> 16.333333 | H39: =+I39&J39&K39&M39 -> SEPTIEMBRESem3939Bryan Amilcar Yax Rivera | I39: =+_xlfn.XLOOKUP(K39,DetalleCalculos!W:W,DetalleCalculos!S:S,"",0,1) -> SEPTIEMBRE | J39: =+"Sem"&K39 -> Sem39 | K39: =+$H$18 -> 39 | L39: =+IF(_xlfn.XLOOKUP(K39,DetalleCalculos!W:W,DetalleCalculos!U:U,0,0,1)=7,1,2) -> 1 | M39: {=+INDEX($B$23:$B$89,ROUNDUP((ROW()-22)/3,0))} -> Bryan Amilcar Yax Rivera | N39: =SUMIFS(DetalleCalculos!$N:$N,DetalleCalculos!$W:$W,$K39,DetalleCalculos!$H:$H,$M39)*24 -> 66 | O39: =SUMIFS(DetalleCalculos!$P:$P,DetalleCalculos!$W:$W,$K39,DetalleCalculos!$H:$H,$M39) -> 44 | P39: =SUMIFS(DetalleCalculos!$Q:$Q,DetalleCalculos!$W:$W,$K39,DetalleCalculos!$H:$H,$M39) -> 0 | Q39: =+IF(L39=1,O39,P39) -> 44 | R39: =+IF(N39-Q39<=0,0,N39-Q39) -> 22 | S39: =_xlfn.XLOOKUP($J39&$K39&$M39,DetalleCalculos!$B:$B,DetalleCalculos!$O:$O,"",0,1) -> 6-0-1 | T39: =+_xlfn.XLOOKUP($S39,'Horarios y Sistemas'!$C:$C,'Horarios y Sistemas'!M:M,0,0,1) -> 1 | U39: =1-T39 -> 0 | V39: =+T39*R39 -> 22 | W39: =+U39*R39 -> 0 | X39: =+V39*X$5 -> 33 | Y39: =+W39*Y$5 -> 0 | Z39: Neto Periodo Proporcional | AA39: =+IF(AA38<=0,0,IF(AND(AA38>AB38,AB38<=0),IF(AA38+AB38>0,AA38+AB38,0),IF(AND(AA38>0,AB38>0),AA38,0))) -> 37.32 | AB39: =+IF(AB38<=0,0,IF(AND(AB38>AA38,AA38<=0),IF(AB38+AA38>0,AB38+AA38,0),IF(AND(AB38>0,AA38>0),AB38,0))) -> 47.28 | AC39: Horas Extras Finales | AD39: =+AA39/$X$5 -> 24.88 | AE39: =+AB39/$Y$5 -> 31.52
B40: ELMER CRISTOBAL LOPEZ HERNANDEZ | C40: =+SUMIFS(AD$23:AD$223,$M$23:$M$223,$B40,$AC$23:$AC$223,$B$20) -> 0 | D40: =+SUMIFS(AE$23:AE$223,$M$23:$M$223,$B40,$AC$23:$AC$223,$B$20) -> 0 | E40: =+SUM(C40:D40) -> 0 | H40: =+I40&J40&K40&M40 -> SEPTIEMBRESem4040Bryan Amilcar Yax Rivera | I40: =+_xlfn.XLOOKUP(K40,DetalleCalculos!W:W,DetalleCalculos!S:S,"",0,1) -> SEPTIEMBRE | J40: =+"Sem"&K40 -> Sem40 | K40: =+$H$19 -> 40 | L40: =+IF(_xlfn.XLOOKUP(K40,DetalleCalculos!W:W,DetalleCalculos!U:U,0,0,1)=7,1,2) -> 1 | M40: {=+INDEX($B$23:$B$89,ROUNDUP((ROW()-22)/3,0))} -> Bryan Amilcar Yax Rivera | N40: =SUMIFS(DetalleCalculos!$N:$N,DetalleCalculos!$W:$W,$K40,DetalleCalculos!$H:$H,$M40)*24 -> 56 | O40: =SUMIFS(DetalleCalculos!$P:$P,DetalleCalculos!$W:$W,$K40,DetalleCalculos!$H:$H,$M40) -> 36 | P40: =SUMIFS(DetalleCalculos!$Q:$Q,DetalleCalculos!$W:$W,$K40,DetalleCalculos!$H:$H,$M40) -> 0 | Q40: =+IF(L40=1,O40,P40) -> 36 | R40: =+IF(N40-Q40<=0,0,N40-Q40) -> 20 | S40: =_xlfn.XLOOKUP($J40&$K40&$M40,DetalleCalculos!$B:$B,DetalleCalculos!$O:$O,"",0,1) -> 0-5-2 | T40: =+_xlfn.XLOOKUP($S40,'Horarios y Sistemas'!$C:$C,'Horarios y Sistemas'!M:M,0,0,1) -> 0 | U40: =1-T40 -> 1 | V40: =+T40*R40 -> 0 | W40: =+U40*R40 -> 20 | X40: =+V40*X$5 -> 0 | Y40: =+W40*Y$5 -> 30
B41: EMERSON ALDAIR BIAN CONTRERAS | C41: =+SUMIFS(AD$23:AD$223,$M$23:$M$223,$B41,$AC$23:$AC$223,$B$20) -> 18.75 | D41: =+SUMIFS(AE$23:AE$223,$M$23:$M$223,$B41,$AC$23:$AC$223,$B$20) -> 21.25 | E41: =+SUM(C41:D41) -> 40 | H41: =+I41&J41&K41&M41 -> SEPTIEMBRESem3838CARLOS ANTONIO DE JESUS DUARTE URIAS | I41: =+_xlfn.XLOOKUP(K41,DetalleCalculos!W:W,DetalleCalculos!S:S,"",0,1) -> SEPTIEMBRE | J41: =+"Sem"&K41 -> Sem38 | K41: =+$H$17 -> 38 | L41: =+IF(_xlfn.XLOOKUP(K41,DetalleCalculos!W:W,DetalleCalculos!U:U,0,0,1)=7,1,2) -> 1 | M41: {=+INDEX($B$23:$B$89,ROUNDUP((ROW()-22)/3,0))} -> CARLOS ANTONIO DE JESUS DUARTE URIAS | N41: =SUMIFS(DetalleCalculos!$N:$N,DetalleCalculos!$W:$W,$K41,DetalleCalculos!$H:$H,$M41)*24 -> 0 | O41: =SUMIFS(DetalleCalculos!$P:$P,DetalleCalculos!$W:$W,$K41,DetalleCalculos!$H:$H,$M41) -> 0 | P41: =SUMIFS(DetalleCalculos!$Q:$Q,DetalleCalculos!$W:$W,$K41,DetalleCalculos!$H:$H,$M41) -> 0 | Q41: =+IF(L41=1,O41,P41) -> 0 | R41: =+IF(N41-Q41<=0,0,N41-Q41) -> 0 | S41: =_xlfn.XLOOKUP($J41&$K41&$M41,DetalleCalculos!$B:$B,DetalleCalculos!$O:$O,"",0,1) | T41: =+_xlfn.XLOOKUP($S41,'Horarios y Sistemas'!$C:$C,'Horarios y Sistemas'!M:M,0,0,1) -> 0 | U41: =1-T41 -> 1 | V41: =+T41*R41 -> 0 | W41: =+U41*R41 -> 0 | X41: =+V41*X$5 -> 0 | Y41: =+W41*Y$5 -> 0 | Z41: Neto Periodo | AA41: =+SUM(X41:X43) -> 0 | AB41: =+SUM(Y41:Y43) -> 0
B42: ERVIN ROLANDO CHINCHILLA ZAMORA | C42: =+SUMIFS(AD$23:AD$223,$M$23:$M$223,$B42,$AC$23:$AC$223,$B$20) -> 22 | D42: =+SUMIFS(AE$23:AE$223,$M$23:$M$223,$B42,$AC$23:$AC$223,$B$20) -> 19 | E42: =+SUM(C42:D42) -> 41 | H42: =+I42&J42&K42&M42 -> SEPTIEMBRESem3939CARLOS ANTONIO DE JESUS DUARTE URIAS | I42: =+_xlfn.XLOOKUP(K42,DetalleCalculos!W:W,DetalleCalculos!S:S,"",0,1) -> SEPTIEMBRE | J42: =+"Sem"&K42 -> Sem39 | K42: =+$H$18 -> 39 | L42: =+IF(_xlfn.XLOOKUP(K42,DetalleCalculos!W:W,DetalleCalculos!U:U,0,0,1)=7,1,2) -> 1 | M42: {=+INDEX($B$23:$B$89,ROUNDUP((ROW()-22)/3,0))} -> CARLOS ANTONIO DE JESUS DUARTE URIAS | N42: =SUMIFS(DetalleCalculos!$N:$N,DetalleCalculos!$W:$W,$K42,DetalleCalculos!$H:$H,$M42)*24 -> 0 | O42: =SUMIFS(DetalleCalculos!$P:$P,DetalleCalculos!$W:$W,$K42,DetalleCalculos!$H:$H,$M42) -> 0 | P42: =SUMIFS(DetalleCalculos!$Q:$Q,DetalleCalculos!$W:$W,$K42,DetalleCalculos!$H:$H,$M42) -> 0 | Q42: =+IF(L42=1,O42,P42) -> 0 | R42: =+IF(N42-Q42<=0,0,N42-Q42) -> 0 | S42: =_xlfn.XLOOKUP($J42&$K42&$M42,DetalleCalculos!$B:$B,DetalleCalculos!$O:$O,"",0,1) | T42: =+_xlfn.XLOOKUP($S42,'Horarios y Sistemas'!$C:$C,'Horarios y Sistemas'!M:M,0,0,1) -> 0 | U42: =1-T42 -> 1 | V42: =+T42*R42 -> 0 | W42: =+U42*R42 -> 0 | X42: =+V42*X$5 -> 0 | Y42: =+W42*Y$5 -> 0 | Z42: Neto Periodo Proporcional | AA42: =+IF(AA41<=0,0,IF(AND(AA41>AB41,AB41<=0),IF(AA41+AB41>0,AA41+AB41,0),IF(AND(AA41>0,AB41>0),AA41,0))) -> 0 | AB42: =+IF(AB41<=0,0,IF(AND(AB41>AA41,AA41<=0),IF(AB41+AA41>0,AB41+AA41,0),IF(AND(AB41>0,AA41>0),AB41,0))) -> 0 | AC42: Horas Extras Finales | AD42: =+AA42/$X$5 -> 0 | AE42: =+AB42/$Y$5 -> 0
B43: ESWIN ESTUARDO ORTEGA LIMA | C43: =+SUMIFS(AD$23:AD$223,$M$23:$M$223,$B43,$AC$23:$AC$223,$B$20) -> 36.75 | D43: =+SUMIFS(AE$23:AE$223,$M$23:$M$223,$B43,$AC$23:$AC$223,$B$20) -> 2.25 | E43: =+SUM(C43:D43) -> 39 | H43: =+I43&J43&K43&M43 -> SEPTIEMBRESem4040CARLOS ANTONIO DE JESUS DUARTE URIAS | I43: =+_xlfn.XLOOKUP(K43,DetalleCalculos!W:W,DetalleCalculos!S:S,"",0,1) -> SEPTIEMBRE | J43: =+"Sem"&K43 -> Sem40 | K43: =+$H$19 -> 40 | L43: =+IF(_xlfn.XLOOKUP(K43,DetalleCalculos!W:W,DetalleCalculos!U:U,0,0,1)=7,1,2) -> 1 | M43: {=+INDEX($B$23:$B$89,ROUNDUP((ROW()-22)/3,0))} -> CARLOS ANTONIO DE JESUS DUARTE URIAS | N43: =SUMIFS(DetalleCalculos!$N:$N,DetalleCalculos!$W:$W,$K43,DetalleCalculos!$H:$H,$M43)*24 -> 0 | O43: =SUMIFS(DetalleCalculos!$P:$P,DetalleCalculos!$W:$W,$K43,DetalleCalculos!$H:$H,$M43) -> 0 | P43: =SUMIFS(DetalleCalculos!$Q:$Q,DetalleCalculos!$W:$W,$K43,DetalleCalculos!$H:$H,$M43) -> 0 | Q43: =+IF(L43=1,O43,P43) -> 0 | R43: =+IF(N43-Q43<=0,0,N43-Q43) -> 0 | S43: =_xlfn.XLOOKUP($J43&$K43&$M43,DetalleCalculos!$B:$B,DetalleCalculos!$O:$O,"",0,1) | T43: =+_xlfn.XLOOKUP($S43,'Horarios y Sistemas'!$C:$C,'Horarios y Sistemas'!M:M,0,0,1) -> 0 | U43: =1-T43 -> 1 | V43: =+T43*R43 -> 0 | W43: =+U43*R43 -> 0 | X43: =+V43*X$5 -> 0 | Y43: =+W43*Y$5 -> 0
B44: EVER GESTRUDES BOLVITO ESTRADA | C44: =+SUMIFS(AD$23:AD$223,$M$23:$M$223,$B44,$AC$23:$AC$223,$B$20) -> 11 | D44: =+SUMIFS(AE$23:AE$223,$M$23:$M$223,$B44,$AC$23:$AC$223,$B$20) -> 0 | E44: =+SUM(C44:D44) -> 11 | H44: =+I44&J44&K44&M44 -> SEPTIEMBRESem3838CARLOS DANIEL RUIZ SANTOS | I44: =+_xlfn.XLOOKUP(K44,DetalleCalculos!W:W,DetalleCalculos!S:S,"",0,1) -> SEPTIEMBRE | J44: =+"Sem"&K44 -> Sem38 | K44: =+$H$17 -> 38 | L44: =+IF(_xlfn.XLOOKUP(K44,DetalleCalculos!W:W,DetalleCalculos!U:U,0,0,1)=7,1,2) -> 1 | M44: {=+INDEX($B$23:$B$89,ROUNDUP((ROW()-22)/3,0))} -> CARLOS DANIEL RUIZ SANTOS | N44: =SUMIFS(DetalleCalculos!$N:$N,DetalleCalculos!$W:$W,$K44,DetalleCalculos!$H:$H,$M44)*24 -> 38 | O44: =SUMIFS(DetalleCalculos!$P:$P,DetalleCalculos!$W:$W,$K44,DetalleCalculos!$H:$H,$M44) -> 44 | P44: =SUMIFS(DetalleCalculos!$Q:$Q,DetalleCalculos!$W:$W,$K44,DetalleCalculos!$H:$H,$M44) -> 0 | Q44: =+IF(L44=1,O44,P44) -> 44 | R44: =+IF(N44-Q44<=0,0,N44-Q44) -> 0 | S44: =_xlfn.XLOOKUP($J44&$K44&$M44,DetalleCalculos!$B:$B,DetalleCalculos!$O:$O,"",0,1) -> 4-0-3 | T44: =+_xlfn.XLOOKUP($S44,'Horarios y Sistemas'!$C:$C,'Horarios y Sistemas'!M:M,0,0,1) -> 1 | U44: =1-T44 -> 0 | V44: =+T44*R44 -> 0 | W44: =+U44*R44 -> 0 | X44: =+V44*X$5 -> 0 | Y44: =+W44*Y$5 -> 0 | Z44: Neto Periodo | AA44: =+SUM(X44:X46) -> 27 | AB44: =+SUM(Y44:Y46) -> 28.5
B45: Edvin Omar Chavez Cuque | C45: =+SUMIFS(AD$23:AD$223,$M$23:$M$223,$B45,$AC$23:$AC$223,$B$20) -> 26 | D45: =+SUMIFS(AE$23:AE$223,$M$23:$M$223,$B45,$AC$23:$AC$223,$B$20) -> 0 | E45: =+SUM(C45:D45) -> 26 | H45: =+I45&J45&K45&M45 -> SEPTIEMBRESem3939CARLOS DANIEL RUIZ SANTOS | I45: =+_xlfn.XLOOKUP(K45,DetalleCalculos!W:W,DetalleCalculos!S:S,"",0,1) -> SEPTIEMBRE | J45: =+"Sem"&K45 -> Sem39 | K45: =+$H$18 -> 39 | L45: =+IF(_xlfn.XLOOKUP(K45,DetalleCalculos!W:W,DetalleCalculos!U:U,0,0,1)=7,1,2) -> 1 | M45: {=+INDEX($B$23:$B$89,ROUNDUP((ROW()-22)/3,0))} -> CARLOS DANIEL RUIZ SANTOS | N45: =SUMIFS(DetalleCalculos!$N:$N,DetalleCalculos!$W:$W,$K45,DetalleCalculos!$H:$H,$M45)*24 -> 62 | O45: =SUMIFS(DetalleCalculos!$P:$P,DetalleCalculos!$W:$W,$K45,DetalleCalculos!$H:$H,$M45) -> 44 | P45: =SUMIFS(DetalleCalculos!$Q:$Q,DetalleCalculos!$W:$W,$K45,DetalleCalculos!$H:$H,$M45) -> 0 | Q45: =+IF(L45=1,O45,P45) -> 44 | R45: =+IF(N45-Q45<=0,0,N45-Q45) -> 18 | S45: =_xlfn.XLOOKUP($J45&$K45&$M45,DetalleCalculos!$B:$B,DetalleCalculos!$O:$O,"",0,1) -> 6-0-1 | T45: =+_xlfn.XLOOKUP($S45,'Horarios y Sistemas'!$C:$C,'Horarios y Sistemas'!M:M,0,0,1) -> 1 | U45: =1-T45 -> 0 | V45: =+T45*R45 -> 18 | W45: =+U45*R45 -> 0 | X45: =+V45*X$5 -> 27 | Y45: =+W45*Y$5 -> 0 | Z45: Neto Periodo Proporcional | AA45: =+IF(AA44<=0,0,IF(AND(AA44>AB44,AB44<=0),IF(AA44+AB44>0,AA44+AB44,0),IF(AND(AA44>0,AB44>0),AA44,0))) -> 27 | AB45: =+IF(AB44<=0,0,IF(AND(AB44>AA44,AA44<=0),IF(AB44+AA44>0,AB44+AA44,0),IF(AND(AB44>0,AA44>0),AB44,0))) -> 28.5 | AC45: Horas Extras Finales | AD45: =+AA45/$X$5 -> 18 | AE45: =+AB45/$Y$5 -> 19
B46: FILIBERTO SACUL CUCUL | C46: =+SUMIFS(AD$23:AD$223,$M$23:$M$223,$B46,$AC$23:$AC$223,$B$20) -> 0 | D46: =+SUMIFS(AE$23:AE$223,$M$23:$M$223,$B46,$AC$23:$AC$223,$B$20) -> 0 | E46: =+SUM(C46:D46) -> 0 | H46: =+I46&J46&K46&M46 -> SEPTIEMBRESem4040CARLOS DANIEL RUIZ SANTOS | I46: =+_xlfn.XLOOKUP(K46,DetalleCalculos!W:W,DetalleCalculos!S:S,"",0,1) -> SEPTIEMBRE | J46: =+"Sem"&K46 -> Sem40 | K46: =+$H$19 -> 40 | L46: =+IF(_xlfn.XLOOKUP(K46,DetalleCalculos!W:W,DetalleCalculos!U:U,0,0,1)=7,1,2) -> 1 | M46: {=+INDEX($B$23:$B$89,ROUNDUP((ROW()-22)/3,0))} -> CARLOS DANIEL RUIZ SANTOS | N46: =SUMIFS(DetalleCalculos!$N:$N,DetalleCalculos!$W:$W,$K46,DetalleCalculos!$H:$H,$M46)*24 -> 55 | O46: =SUMIFS(DetalleCalculos!$P:$P,DetalleCalculos!$W:$W,$K46,DetalleCalculos!$H:$H,$M46) -> 36 | P46: =SUMIFS(DetalleCalculos!$Q:$Q,DetalleCalculos!$W:$W,$K46,DetalleCalculos!$H:$H,$M46) -> 0 | Q46: =+IF(L46=1,O46,P46) -> 36 | R46: =+IF(N46-Q46<=0,0,N46-Q46) -> 19 | S46: =_xlfn.XLOOKUP($J46&$K46&$M46,DetalleCalculos!$B:$B,DetalleCalculos!$O:$O,"",0,1) -> 0-5-2 | T46: =+_xlfn.XLOOKUP($S46,'Horarios y Sistemas'!$C:$C,'Horarios y Sistemas'!M:M,0,0,1) -> 0 | U46: =1-T46 -> 1 | V46: =+T46*R46 -> 0 | W46: =+U46*R46 -> 19 | X46: =+V46*X$5 -> 0 | Y46: =+W46*Y$5 -> 28.5
...

Sheet DetalleCalculos
O2: Info Base de Datos | P2: Info Horarios | Q2: Fechas | R2: Turnos
I6: Formulas | J6: 1 | K6: 2 | L6: 3 = 2-1 | M6: 4 | N6: 5 = 3-4
B7: Codigo1 | C7: Codigo 2 | D7: Codigo 3 | E7: Codigo 4 | F7: Codigo 5 | H7: Empleado | I7: Tipo de Turno | J7: Turno Ingreso | K7: Turno Egreso | L7: Horas Presenciadas | M7: Hora de Almuerzo/Cena | N7: Hora Efectiva | O7: Sistema | P7: Ordinarias Semana Completa | Q7: Ordinarias Semana dividida | R7: Total Ordinarias | S7: MES | T7: Semana | U7: Dias de la Semana | V7: Fecha | W7: Semana | X7: Dia del mes | Y7: Dia | Z7: Dia Semana | AA7: DIA | AB7: NOCHE | AC7: DESCANSO | AD7: ASUETO-D | AE7: ASUETO-N
B8: =+T8&W8&H8 -> Sem3838ADOLFO DE JESUS LOPEZ CHAVEZ | C8: =+S8&T8 -> SEPTIEMBRESem38 | D8: =+S8&T8&H8 -> SEPTIEMBRESem38ADOLFO DE JESUS LOPEZ CHAVEZ | E8: =+S8&T8&W8&H8 -> SEPTIEMBRESem3838ADOLFO DE JESUS LOPEZ CHAVEZ | F8: =+H8&V8 -> ADOLFO DE JESUS LOPEZ CHAVEZ46279 | H8: ADOLFO DE JESUS LOPEZ CHAVEZ | I8: =+_xlfn.XLOOKUP($H8&$V8,BASEDATOS!$B:$B,BASEDATOS!F:F,0,0,1) -> DESCANSO | J8: =+_xlfn.XLOOKUP($H8&$V8,BASEDATOS!$B:$B,BASEDATOS!Q:Q,0,0,1) -> 0 | K8: =+_xlfn.XLOOKUP($H8&$V8,BASEDATOS!$B:$B,BASEDATOS!R:R,0,0,1) -> 0 | L8: =+IF(OR(J8="Descanso",J8="AUSENTE",J8="ASUETO"),0,MOD(K8-J8,1)) -> 0 | M8: =+IF(OR(I8="DIA",I8="NOCHE",I8="MIXTO"),"1:00",0) -> 0 | N8: =+IF(I8="ASUETO-D",8/24,IF(I8="ASUETO-N",6/24,MOD(L8-M8,1))) -> 0 | O8: =+O14 -> 5-0-2 | P8: =+IF(AND(Y8="Domingo",U8=7),_xlfn.XLOOKUP(O8,'Horarios y Sistemas'!C:C,'Horarios y Sistemas'!H:H,0,0,1),0) -> 0 | Q8: =IF(U8=U9,0,IF(AVERAGEIF(W:W,W8,U:U)=U8,0,_xlfn.XLOOKUP(O8,'Horarios y Sistemas'!C:C,'Horarios y Sistemas'!H:H,0,0,1)-P8))/7*U8 -> 0 | R8: =+IF(Y8="Domingo",SUM(P2:Q8),0) -> 0 | S8: =+UPPER(TEXT(V8,"MMMMMMMM")) -> SEPTIEMBRE | T8: =+"Sem"&W8 -> Sem38 | U8: =+COUNTIF(B:B,B8) -> 7 | V8: 46279 | W8: =+_xlfn.ISOWEEKNUM(V8) -> 38 | X8: =+DAY(V8) -> 14 | Y8: Lunes | Z8: 1 | AA8: =+IF($I8=AA$7,1,0) -> 0 | AB8: =+IF($I8=AB$7,1,0) -> 0 | AC8: =+IF($I8=AC$7,1,0) -> 1 | AD8: =+IF($I8=AD$7,1,0) -> 0 | AE8: =+IF($I8=AE$7,1,0) -> 0
B9: =+T9&W9&H9 -> Sem3838ADOLFO DE JESUS LOPEZ CHAVEZ | C9: =+S9&T9 -> SEPTIEMBRESem38 | D9: =+S9&T9&H9 -> SEPTIEMBRESem38ADOLFO DE JESUS LOPEZ CHAVEZ | E9: =+S9&T9&W9&H9 -> SEPTIEMBRESem3838ADOLFO DE JESUS LOPEZ CHAVEZ | F9: =+H9&V9 -> ADOLFO DE JESUS LOPEZ CHAVEZ46280 | H9: ADOLFO DE JESUS LOPEZ CHAVEZ | I9: =+_xlfn.XLOOKUP($H9&$V9,BASEDATOS!$B:$B,BASEDATOS!F:F,0,0,1) -> DIA | J9: =+_xlfn.XLOOKUP($H9&$V9,BASEDATOS!$B:$B,BASEDATOS!Q:Q,0,0,1) -> 0.33333333 | K9: =+_xlfn.XLOOKUP($H9&$V9,BASEDATOS!$B:$B,BASEDATOS!R:R,0,0,1) -> 0.70833333 | L9: =+IF(OR(J9="Descanso",J9="AUSENTE",J9="ASUETO"),0,MOD(K9-J9,1)) -> 0.375 | M9: =+IF(OR(I9="DIA",I9="NOCHE",I9="MIXTO"),"1:00",0) -> 1:00 | N9: =+IF(I9="ASUETO-D",8/24,IF(I9="ASUETO-N",6/24,MOD(L9-M9,1))) -> 0.33333333 | O9: =+O14 -> 5-0-2 | P9: =+IF(AND(Y9="Domingo",U9=7),_xlfn.XLOOKUP(O9,'Horarios y Sistemas'!C:C,'Horarios y Sistemas'!H:H,0,0,1),0) -> 0 | Q9: =IF(U9=U10,0,IF(AVERAGEIF(W:W,W9,U:U)=U9,0,_xlfn.XLOOKUP(O9,'Horarios y Sistemas'!C:C,'Horarios y Sistemas'!H:H,0,0,1)-P9))/7*U9 -> 0 | R9: =+IF(Y9="Domingo",SUM(P3:Q9),0) -> 0 | S9: =+UPPER(TEXT(V9,"MMMMMMMM")) -> SEPTIEMBRE | T9: =+"Sem"&W9 -> Sem38 | U9: =+COUNTIF(B:B,B9) -> 7 | V9: 46280 | W9: =+_xlfn.ISOWEEKNUM(V9) -> 38 | X9: =+DAY(V9) -> 15 | Y9: Martes | Z9: 2 | AA9: =+IF($I9=AA$7,1,0) -> 1 | AB9: =+IF($I9=AB$7,1,0) -> 0 | AC9: =+IF($I9=AC$7,1,0) -> 0 | AD9: =+IF($I9=AD$7,1,0) -> 0 | AE9: =+IF($I9=AE$7,1,0) -> 0
B10: =+T10&W10&H10 -> Sem3838ADOLFO DE JESUS LOPEZ CHAVEZ | C10: =+S10&T10 -> SEPTIEMBRESem38 | D10: =+S10&T10&H10 -> SEPTIEMBRESem38ADOLFO DE JESUS LOPEZ CHAVEZ | E10: =+S10&T10&W10&H10 -> SEPTIEMBRESem3838ADOLFO DE JESUS LOPEZ CHAVEZ | F10: =+H10&V10 -> ADOLFO DE JESUS LOPEZ CHAVEZ46281 | H10: ADOLFO DE JESUS LOPEZ CHAVEZ | I10: =+_xlfn.XLOOKUP($H10&$V10,BASEDATOS!$B:$B,BASEDATOS!F:F,0,0,1) -> DIA | J10: =+_xlfn.XLOOKUP($H10&$V10,BASEDATOS!$B:$B,BASEDATOS!Q:Q,0,0,1) -> 0.23958333 | K10: =+_xlfn.XLOOKUP($H10&$V10,BASEDATOS!$B:$B,BASEDATOS!R:R,0,0,1) -> 0.75 | L10: =+IF(OR(J10="Descanso",J10="AUSENTE",J10="ASUETO"),0,MOD(K10-J10,1)) -> 0.51041667 | M10: =+IF(OR(I10="DIA",I10="NOCHE",I10="MIXTO"),"1:00",0) -> 1:00 | N10: =+IF(I10="ASUETO-D",8/24,IF(I10="ASUETO-N",6/24,MOD(L10-M10,1))) -> 0.46875 | O10: =+O14 -> 5-0-2 | P10: =+IF(AND(Y10="Domingo",U10=7),_xlfn.XLOOKUP(O10,'Horarios y Sistemas'!C:C,'Horarios y Sistemas'!H:H,0,0,1),0) -> 0 | Q10: =IF(U10=U11,0,IF(AVERAGEIF(W:W,W10,U:U)=U10,0,_xlfn.XLOOKUP(O10,'Horarios y Sistemas'!C:C,'Horarios y Sistemas'!H:H,0,0,1)-P10))/7*U10 -> 0 | R10: =+IF(Y10="Domingo",SUM(P4:Q10),0) -> 0 | S10: =+UPPER(TEXT(V10,"MMMMMMMM")) -> SEPTIEMBRE | T10: =+"Sem"&W10 -> Sem38 | U10: =+COUNTIF(B:B,B10) -> 7 | V10: 46281 | W10: =+_xlfn.ISOWEEKNUM(V10) -> 38 | X10: =+DAY(V10) -> 16 | Y10: Miércoles | Z10: 3 | AA10: =+IF($I10=AA$7,1,0) -> 1 | AB10: =+IF($I10=AB$7,1,0) -> 0 | AC10: =+IF($I10=AC$7,1,0) -> 0 | AD10: =+IF($I10=AD$7,1,0) -> 0 | AE10: =+IF($I10=AE$7,1,0) -> 0
B11: =+T11&W11&H11 -> Sem3838ADOLFO DE JESUS LOPEZ CHAVEZ | C11: =+S11&T11 -> SEPTIEMBRESem38 | D11: =+S11&T11&H11 -> SEPTIEMBRESem38ADOLFO DE JESUS LOPEZ CHAVEZ | E11: =+S11&T11&W11&H11 -> SEPTIEMBRESem3838ADOLFO DE JESUS LOPEZ CHAVEZ | F11: =+H11&V11 -> ADOLFO DE JESUS LOPEZ CHAVEZ46282 | H11: ADOLFO DE JESUS LOPEZ CHAVEZ | I11: =+_xlfn.XLOOKUP($H11&$V11,BASEDATOS!$B:$B,BASEDATOS!F:F,0,0,1) -> DIA | J11: =+_xlfn.XLOOKUP($H11&$V11,BASEDATOS!$B:$B,BASEDATOS!Q:Q,0,0,1) -> 0.23958333 | K11: =+_xlfn.XLOOKUP($H11&$V11,BASEDATOS!$B:$B,BASEDATOS!R:R,0,0,1) -> 0.75 | L11: =+IF(OR(J11="Descanso",J11="AUSENTE",J11="ASUETO"),0,MOD(K11-J11,1)) -> 0.51041667 | M11: =+IF(OR(I11="DIA",I11="NOCHE",I11="MIXTO"),"1:00",0) -> 1:00 | N11: =+IF(I11="ASUETO-D",8/24,IF(I11="ASUETO-N",6/24,MOD(L11-M11,1))) -> 0.46875 | O11: =+O14 -> 5-0-2 | P11: =+IF(AND(Y11="Domingo",U11=7),_xlfn.XLOOKUP(O11,'Horarios y Sistemas'!C:C,'Horarios y Sistemas'!H:H,0,0,1),0) -> 0 | Q11: =IF(U11=U12,0,IF(AVERAGEIF(W:W,W11,U:U)=U11,0,_xlfn.XLOOKUP(O11,'Horarios y Sistemas'!C:C,'Horarios y Sistemas'!H:H,0,0,1)-P11))/7*U11 -> 0 | R11: =+IF(Y11="Domingo",SUM(P5:Q11),0) -> 0 | S11: =+UPPER(TEXT(V11,"MMMMMMMM")) -> SEPTIEMBRE | T11: =+"Sem"&W11 -> Sem38 | U11: =+COUNTIF(B:B,B11) -> 7 | V11: 46282 | W11: =+_xlfn.ISOWEEKNUM(V11) -> 38 | X11: =+DAY(V11) -> 17 | Y11: Jueves | Z11: 4 | AA11: =+IF($I11=AA$7,1,0) -> 1 | AB11: =+IF($I11=AB$7,1,0) -> 0 | AC11: =+IF($I11=AC$7,1,0) -> 0 | AD11: =+IF($I11=AD$7,1,0) -> 0 | AE11: =+IF($I11=AE$7,1,0) -> 0
B12: =+T12&W12&H12 -> Sem3838ADOLFO DE JESUS LOPEZ CHAVEZ | C12: =+S12&T12 -> SEPTIEMBRESem38 | D12: =+S12&T12&H12 -> SEPTIEMBRESem38ADOLFO DE JESUS LOPEZ CHAVEZ | E12: =+S12&T12&W12&H12 -> SEPTIEMBRESem3838ADOLFO DE JESUS LOPEZ CHAVEZ | F12: =+H12&V12 -> ADOLFO DE JESUS LOPEZ CHAVEZ46283 | H12: ADOLFO DE JESUS LOPEZ CHAVEZ | I12: =+_xlfn.XLOOKUP($H12&$V12,BASEDATOS!$B:$B,BASEDATOS!F:F,0,0,1) -> DIA | J12: =+_xlfn.XLOOKUP($H12&$V12,BASEDATOS!$B:$B,BASEDATOS!Q:Q,0,0,1) -> 0.23958333 | K12: =+_xlfn.XLOOKUP($H12&$V12,BASEDATOS!$B:$B,BASEDATOS!R:R,0,0,1) -> 0.75 | L12: =+IF(OR(J12="Descanso",J12="AUSENTE",J12="ASUETO"),0,MOD(K12-J12,1)) -> 0.51041667 | M12: =+IF(OR(I12="DIA",I12="NOCHE",I12="MIXTO"),"1:00",0) -> 1:00 | N12: =+IF(I12="ASUETO-D",8/24,IF(I12="ASUETO-N",6/24,MOD(L12-M12,1))) -> 0.46875 | O12: =+O14 -> 5-0-2 | P12: =+IF(AND(Y12="Domingo",U12=7),_xlfn.XLOOKUP(O12,'Horarios y Sistemas'!C:C,'Horarios y Sistemas'!H:H,0,0,1),0) -> 0 | Q12: =IF(U12=U13,0,IF(AVERAGEIF(W:W,W12,U:U)=U12,0,_xlfn.XLOOKUP(O12,'Horarios y Sistemas'!C:C,'Horarios y Sistemas'!H:H,0,0,1)-P12))/7*U12 -> 0 | R12: =+IF(Y12="Domingo",SUM(P6:Q12),0) -> 0 | S12: =+UPPER(TEXT(V12,"MMMMMMMM")) -> SEPTIEMBRE | T12: =+"Sem"&W12 -> Sem38 | U12: =+COUNTIF(B:B,B12) -> 7 | V12: 46283 | W12: =+_xlfn.ISOWEEKNUM(V12) -> 38 | X12: =+DAY(V12) -> 18 | Y12: Viernes | Z12: 5 | AA12: =+IF($I12=AA$7,1,0) -> 1 | AB12: =+IF($I12=AB$7,1,0) -> 0 | AC12: =+IF($I12=AC$7,1,0) -> 0 | AD12: =+IF($I12=AD$7,1,0) -> 0 | AE12: =+IF($I12=AE$7,1,0) -> 0
B13: =+T13&W13&H13 -> Sem3838ADOLFO DE JESUS LOPEZ CHAVEZ | C13: =+S13&T13 -> SEPTIEMBRESem38 | D13: =+S13&T13&H13 -> SEPTIEMBRESem38ADOLFO DE JESUS LOPEZ CHAVEZ | E13: =+S13&T13&W13&H13 -> SEPTIEMBRESem3838ADOLFO DE JESUS LOPEZ CHAVEZ | F13: =+H13&V13 -> ADOLFO DE JESUS LOPEZ CHAVEZ46284 | H13: ADOLFO DE JESUS LOPEZ CHAVEZ | I13: =+_xlfn.XLOOKUP($H13&$V13,BASEDATOS!$B:$B,BASEDATOS!F:F,0,0,1) -> DIA | J13: =+_xlfn.XLOOKUP($H13&$V13,BASEDATOS!$B:$B,BASEDATOS!Q:Q,0,0,1) -> 0.23958333 | K13: =+_xlfn.XLOOKUP($H13&$V13,BASEDATOS!$B:$B,BASEDATOS!R:R,0,0,1) -> 0.58333333 | L13: =+IF(OR(J13="Descanso",J13="AUSENTE",J13="ASUETO"),0,MOD(K13-J13,1)) -> 0.34375 | M13: =+IF(OR(I13="DIA",I13="NOCHE",I13="MIXTO"),"1:00",0) -> 1:00 | N13: =+IF(I13="ASUETO-D",8/24,IF(I13="ASUETO-N",6/24,MOD(L13-M13,1))) -> 0.30208333 | O13: =+O14 -> 5-0-2 | P13: =+IF(AND(Y13="Domingo",U13=7),_xlfn.XLOOKUP(O13,'Horarios y Sistemas'!C:C,'Horarios y Sistemas'!H:H,0,0,1),0) -> 0 | Q13: =IF(U13=U14,0,IF(AVERAGEIF(W:W,W13,U:U)=U13,0,_xlfn.XLOOKUP(O13,'Horarios y Sistemas'!C:C,'Horarios y Sistemas'!H:H,0,0,1)-P13))/7*U13 -> 0 | R13: =+IF(Y13="Domingo",SUM(P7:Q13),0) -> 0 | S13: =+UPPER(TEXT(V13,"MMMMMMMM")) -> SEPTIEMBRE | T13: =+"Sem"&W13 -> Sem38 | U13: =+COUNTIF(B:B,B13) -> 7 | V13: 46284 | W13: =+_xlfn.ISOWEEKNUM(V13) -> 38 | X13: =+DAY(V13) -> 19 | Y13: Sábado | Z13: 6 | AA13: =+IF($I13=AA$7,1,0) -> 1 | AB13: =+IF($I13=AB$7,1,0) -> 0 | AC13: =+IF($I13=AC$7,1,0) -> 0 | AD13: =+IF($I13=AD$7,1,0) -> 0 | AE13: =+IF($I13=AE$7,1,0) -> 0
B14: =+T14&W14&H14 -> Sem3838ADOLFO DE JESUS LOPEZ CHAVEZ | C14: =+S14&T14 -> SEPTIEMBRESem38 | D14: =+S14&T14&H14 -> SEPTIEMBRESem38ADOLFO DE JESUS LOPEZ CHAVEZ | E14: =+S14&T14&W14&H14 -> SEPTIEMBRESem3838ADOLFO DE JESUS LOPEZ CHAVEZ | F14: =+H14&V14 -> ADOLFO DE JESUS LOPEZ CHAVEZ46285 | H14: ADOLFO DE JESUS LOPEZ CHAVEZ | I14: =+_xlfn.XLOOKUP($H14&$V14,BASEDATOS!$B:$B,BASEDATOS!F:F,0,0,1) -> DESCANSO | J14: =+_xlfn.XLOOKUP($H14&$V14,BASEDATOS!$B:$B,BASEDATOS!Q:Q,0,0,1) -> 0 | K14: =+_xlfn.XLOOKUP($H14&$V14,BASEDATOS!$B:$B,BASEDATOS!R:R,0,0,1) -> 0 | L14: =+IF(OR(J14="Descanso",J14="AUSENTE",J14="ASUETO"),0,MOD(K14-J14,1)) -> 0 | M14: =+IF(OR(I14="DIA",I14="NOCHE",I14="MIXTO"),"1:00",0) -> 0 | N14: =+IF(I14="ASUETO-D",8/24,IF(I14="ASUETO-N",6/24,MOD(L14-M14,1))) -> 0 | O14: =+IF(Y14="Domingo",SUM(AA8:AA14)&"-"&SUM(AB8:AB14)&"-"&SUM(AC8:AE14),"") -> 5-0-2 | P14: =+IF(AND(Y14="Domingo",U14=7),_xlfn.XLOOKUP(O14,'Horarios y Sistemas'!C:C,'Horarios y Sistemas'!H:H,0,0,1),0) -> 44 | Q14: =IF(U14=U15,0,IF(AVERAGEIF(W:W,W14,U:U)=U14,0,_xlfn.XLOOKUP(O14,'Horarios y Sistemas'!C:C,'Horarios y Sistemas'!H:H,0,0,1)-P14))/7*U14 -> 0 | R14: =+IF(Y14="Domingo",SUM(P8:Q14),0) -> 44 | S14: =+UPPER(TEXT(V14,"MMMMMMMM")) -> SEPTIEMBRE | T14: =+"Sem"&W14 -> Sem38 | U14: =+COUNTIF(B:B,B14) -> 7 | V14: 46285 | W14: =+_xlfn.ISOWEEKNUM(V14) -> 38 | X14: =+DAY(V14) -> 20 | Y14: Domingo | Z14: 7 | AA14: =+IF($I14=AA$7,1,0) -> 0 | AB14: =+IF($I14=AB$7,1,0) -> 0 | AC14: =+IF($I14=AC$7,1,0) -> 1 | AD14: =+IF($I14=AD$7,1,0) -> 0 | AE14: =+IF($I14=AE$7,1,0) -> 0
B15: =+T15&W15&H15 -> Sem3939ADOLFO DE JESUS LOPEZ CHAVEZ | C15: =+S15&T15 -> SEPTIEMBRESem39 | D15: =+S15&T15&H15 -> SEPTIEMBRESem39ADOLFO DE JESUS LOPEZ CHAVEZ | E15: =+S15&T15&W15&H15 -> SEPTIEMBRESem3939ADOLFO DE JESUS LOPEZ CHAVEZ | F15: =+H15&V15 -> ADOLFO DE JESUS LOPEZ CHAVEZ46286 | H15: ADOLFO DE JESUS LOPEZ CHAVEZ | I15: =+_xlfn.XLOOKUP($H15&$V15,BASEDATOS!$B:$B,BASEDATOS!F:F,0,0,1) -> NOCHE | J15: =+_xlfn.XLOOKUP($H15&$V15,BASEDATOS!$B:$B,BASEDATOS!Q:Q,0,0,1) -> 0.73958333 | K15: =+_xlfn.XLOOKUP($H15&$V15,BASEDATOS!$B:$B,BASEDATOS!R:R,0,0,1) -> 0.25 | L15: =+IF(OR(J15="Descanso",J15="AUSENTE",J15="ASUETO"),0,MOD(K15-J15,1)) -> 0.51041667 | M15: =+IF(OR(I15="DIA",I15="NOCHE",I15="MIXTO"),"1:00",0) -> 1:00 | N15: =+IF(I15="ASUETO-D",8/24,IF(I15="ASUETO-N",6/24,MOD(L15-M15,1))) -> 0.46875 | O15: =+O21 -> 0-5-2 | P15: =+IF(AND(Y15="Domingo",U15=7),_xlfn.XLOOKUP(O15,'Horarios y Sistemas'!C:C,'Horarios y Sistemas'!H:H,0,0,1),0) -> 0 | Q15: =IF(U15=U16,0,IF(AVERAGEIF(W:W,W15,U:U)=U15,0,_xlfn.XLOOKUP(O15,'Horarios y Sistemas'!C:C,'Horarios y Sistemas'!H:H,0,0,1)-P15))/7*U15 -> 0 | R15: =+IF(Y15="Domingo",SUM(P9:Q15),0) -> 0 | S15: =+UPPER(TEXT(V15,"MMMMMMMM")) -> SEPTIEMBRE | T15: =+"Sem"&W15 -> Sem39 | U15: =+COUNTIF(B:B,B15) -> 7 | V15: 46286 | W15: =+_xlfn.ISOWEEKNUM(V15) -> 39 | X15: =+DAY(V15) -> 21 | Y15: Lunes | Z15: 1 | AA15: =+IF($I15=AA$7,1,0) -> 0 | AB15: =+IF($I15=AB$7,1,0) -> 1 | AC15: =+IF($I15=AC$7,1,0) -> 0 | AD15: =+IF($I15=AD$7,1,0) -> 0 | AE15: =+IF($I15=AE$7,1,0) -> 0
B16: =+T16&W16&H16 -> Sem3939ADOLFO DE JESUS LOPEZ CHAVEZ | C16: =+S16&T16 -> SEPTIEMBRESem39 | D16: =+S16&T16&H16 -> SEPTIEMBRESem39ADOLFO DE JESUS LOPEZ CHAVEZ | E16: =+S16&T16&W16&H16 -> SEPTIEMBRESem3939ADOLFO DE JESUS LOPEZ CHAVEZ | F16: =+H16&V16 -> ADOLFO DE JESUS LOPEZ CHAVEZ46287 | H16: ADOLFO DE JESUS LOPEZ CHAVEZ | I16: =+_xlfn.XLOOKUP($H16&$V16,BASEDATOS!$B:$B,BASEDATOS!F:F,0,0,1) -> NOCHE | J16: =+_xlfn.XLOOKUP($H16&$V16,BASEDATOS!$B:$B,BASEDATOS!Q:Q,0,0,1) -> 0.73958333 | K16: =+_xlfn.XLOOKUP($H16&$V16,BASEDATOS!$B:$B,BASEDATOS!R:R,0,0,1) -> 0.25 | L16: =+IF(OR(J16="Descanso",J16="AUSENTE",J16="ASUETO"),0,MOD(K16-J16,1)) -> 0.51041667 | M16: =+IF(OR(I16="DIA",I16="NOCHE",I16="MIXTO"),"1:00",0) -> 1:00 | N16: =+IF(I16="ASUETO-D",8/24,IF(I16="ASUETO-N",6/24,MOD(L16-M16,1))) -> 0.46875 | O16: =+O21 -> 0-5-2 | P16: =+IF(AND(Y16="Domingo",U16=7),_xlfn.XLOOKUP(O16,'Horarios y Sistemas'!C:C,'Horarios y Sistemas'!H:H,0,0,1),0) -> 0 | Q16: =IF(U16=U17,0,IF(AVERAGEIF(W:W,W16,U:U)=U16,0,_xlfn.XLOOKUP(O16,'Horarios y Sistemas'!C:C,'Horarios y Sistemas'!H:H,0,0,1)-P16))/7*U16 -> 0 | R16: =+IF(Y16="Domingo",SUM(P10:Q16),0) -> 0 | S16: =+UPPER(TEXT(V16,"MMMMMMMM")) -> SEPTIEMBRE | T16: =+"Sem"&W16 -> Sem39 | U16: =+COUNTIF(B:B,B16) -> 7 | V16: 46287 | W16: =+_xlfn.ISOWEEKNUM(V16) -> 39 | X16: =+DAY(V16) -> 22 | Y16: Martes | Z16: 2 | AA16: =+IF($I16=AA$7,1,0) -> 0 | AB16: =+IF($I16=AB$7,1,0) -> 1 | AC16: =+IF($I16=AC$7,1,0) -> 0 | AD16: =+IF($I16=AD$7,1,0) -> 0 | AE16: =+IF($I16=AE$7,1,0) -> 0
B17: =+T17&W17&H17 -> Sem3939ADOLFO DE JESUS LOPEZ CHAVEZ | C17: =+S17&T17 -> SEPTIEMBRESem39 | D17: =+S17&T17&H17 -> SEPTIEMBRESem39ADOLFO DE JESUS LOPEZ CHAVEZ | E17: =+S17&T17&W17&H17 -> SEPTIEMBRESem3939ADOLFO DE JESUS LOPEZ CHAVEZ | F17: =+H17&V17 -> ADOLFO DE JESUS LOPEZ CHAVEZ46288 | H17: ADOLFO DE JESUS LOPEZ CHAVEZ | I17: =+_xlfn.XLOOKUP($H17&$V17,BASEDATOS!$B:$B,BASEDATOS!F:F,0,0,1) -> NOCHE | J17: =+_xlfn.XLOOKUP($H17&$V17,BASEDATOS!$B:$B,BASEDATOS!Q:Q,0,0,1) -> 0.73958333 | K17: =+_xlfn.XLOOKUP($H17&$V17,BASEDATOS!$B:$B,BASEDATOS!R:R,0,0,1) -> 0.25 | L17: =+IF(OR(J17="Descanso",J17="AUSENTE",J17="ASUETO"),0,MOD(K17-J17,1)) -> 0.51041667 | M17: =+IF(OR(I17="DIA",I17="NOCHE",I17="MIXTO"),"1:00",0) -> 1:00 | N17: =+IF(I17="ASUETO-D",8/24,IF(I17="ASUETO-N",6/24,MOD(L17-M17,1))) -> 0.46875 | O17: =+O21 -> 0-5-2 | P17: =+IF(AND(Y17="Domingo",U17=7),_xlfn.XLOOKUP(O17,'Horarios y Sistemas'!C:C,'Horarios y Sistemas'!H:H,0,0,1),0) -> 0 | Q17: =IF(U17=U18,0,IF(AVERAGEIF(W:W,W17,U:U)=U17,0,_xlfn.XLOOKUP(O17,'Horarios y Sistemas'!C:C,'Horarios y Sistemas'!H:H,0,0,1)-P17))/7*U17 -> 0 | R17: =+IF(Y17="Domingo",SUM(P11:Q17),0) -> 0 | S17: =+UPPER(TEXT(V17,"MMMMMMMM")) -> SEPTIEMBRE | T17: =+"Sem"&W17 -> Sem39 | U17: =+COUNTIF(B:B,B17) -> 7 | V17: 46288 | W17: =+_xlfn.ISOWEEKNUM(V17) -> 39 | X17: =+DAY(V17) -> 23 | Y17: Miércoles | Z17: 3 | AA17: =+IF($I17=AA$7,1,0) -> 0 | AB17: =+IF($I17=AB$7,1,0) -> 1 | AC17: =+IF($I17=AC$7,1,0) -> 0 | AD17: =+IF($I17=AD$7,1,0) -> 0 | AE17: =+IF($I17=AE$7,1,0) -> 0
B18: =+T18&W18&H18 -> Sem3939ADOLFO DE JESUS LOPEZ CHAVEZ | C18: =+S18&T18 -> SEPTIEMBRESem39 | D18: =+S18&T18&H18 -> SEPTIEMBRESem39ADOLFO DE JESUS LOPEZ CHAVEZ | E18: =+S18&T18&W18&H18 -> SEPTIEMBRESem3939ADOLFO DE JESUS LOPEZ CHAVEZ | F18: =+H18&V18 -> ADOLFO DE JESUS LOPEZ CHAVEZ46289 | H18: ADOLFO DE JESUS LOPEZ CHAVEZ | I18: =+_xlfn.XLOOKUP($H18&$V18,BASEDATOS!$B:$B,BASEDATOS!F:F,0,0,1) -> NOCHE | J18: =+_xlfn.XLOOKUP($H18&$V18,BASEDATOS!$B:$B,BASEDATOS!Q:Q,0,0,1) -> 0.73958333 | K18: =+_xlfn.XLOOKUP($H18&$V18,BASEDATOS!$B:$B,BASEDATOS!R:R,0,0,1) -> 0.25 | L18: =+IF(OR(J18="Descanso",J18="AUSENTE",J18="ASUETO"),0,MOD(K18-J18,1)) -> 0.51041667 | M18: =+IF(OR(I18="DIA",I18="NOCHE",I18="MIXTO"),"1:00",0) -> 1:00 | N18: =+IF(I18="ASUETO-D",8/24,IF(I18="ASUETO-N",6/24,MOD(L18-M18,1))) -> 0.46875 | O18: =+O21 -> 0-5-2 | P18: =+IF(AND(Y18="Domingo",U18=7),_xlfn.XLOOKUP(O18,'Horarios y Sistemas'!C:C,'Horarios y Sistemas'!H:H,0,0,1),0) -> 0 | Q18: =IF(U18=U19,0,IF(AVERAGEIF(W:W,W18,U:U)=U18,0,_xlfn.XLOOKUP(O18,'Horarios y Sistemas'!C:C,'Horarios y Sistemas'!H:H,0,0,1)-P18))/7*U18 -> 0 | R18: =+IF(Y18="Domingo",SUM(P12:Q18),0) -> 0 | S18: =+UPPER(TEXT(V18,"MMMMMMMM")) -> SEPTIEMBRE | T18: =+"Sem"&W18 -> Sem39 | U18: =+COUNTIF(B:B,B18) -> 7 | V18: 46289 | W18: =+_xlfn.ISOWEEKNUM(V18) -> 39 | X18: =+DAY(V18) -> 24 | Y18: Jueves | Z18: 4 | AA18: =+IF($I18=AA$7,1,0) -> 0 | AB18: =+IF($I18=AB$7,1,0) -> 1 | AC18: =+IF($I18=AC$7,1,0) -> 0 | AD18: =+IF($I18=AD$7,1,0) -> 0 | AE18: =+IF($I18=AE$7,1,0) -> 0
B19: =+T19&W19&H19 -> Sem3939ADOLFO DE JESUS LOPEZ CHAVEZ | C19: =+S19&T19 -> SEPTIEMBRESem39 | D19: =+S19&T19&H19 -> SEPTIEMBRESem39ADOLFO DE JESUS LOPEZ CHAVEZ | E19: =+S19&T19&W19&H19 -> SEPTIEMBRESem3939ADOLFO DE JESUS LOPEZ CHAVEZ | F19: =+H19&V19 -> ADOLFO DE JESUS LOPEZ CHAVEZ46290 | H19: ADOLFO DE JESUS LOPEZ CHAVEZ | I19: =+_xlfn.XLOOKUP($H19&$V19,BASEDATOS!$B:$B,BASEDATOS!F:F,0,0,1) -> NOCHE | J19: =+_xlfn.XLOOKUP($H19&$V19,BASEDATOS!$B:$B,BASEDATOS!Q:Q,0,0,1) -> 0.73958333 | K19: =+_xlfn.XLOOKUP($H19&$V19,BASEDATOS!$B:$B,BASEDATOS!R:R,0,0,1) -> 0.25 | L19: =+IF(OR(J19="Descanso",J19="AUSENTE",J19="ASUETO"),0,MOD(K19-J19,1)) -> 0.51041667 | M19: =+IF(OR(I19="DIA",I19="NOCHE",I19="MIXTO"),"1:00",0) -> 1:00 | N19: =+IF(I19="ASUETO-D",8/24,IF(I19="ASUETO-N",6/24,MOD(L19-M19,1))) -> 0.46875 | O19: =+O21 -> 0-5-2 | P19: =+IF(AND(Y19="Domingo",U19=7),_xlfn.XLOOKUP(O19,'Horarios y Sistemas'!C:C,'Horarios y Sistemas'!H:H,0,0,1),0) -> 0 | Q19: =IF(U19=U20,0,IF(AVERAGEIF(W:W,W19,U:U)=U19,0,_xlfn.XLOOKUP(O19,'Horarios y Sistemas'!C:C,'Horarios y Sistemas'!H:H,0,0,1)-P19))/7*U19 -> 0 | R19: =+IF(Y19="Domingo",SUM(P13:Q19),0) -> 0 | S19: =+UPPER(TEXT(V19,"MMMMMMMM")) -> SEPTIEMBRE | T19: =+"Sem"&W19 -> Sem39 | U19: =+COUNTIF(B:B,B19) -> 7 | V19: 46290 | W19: =+_xlfn.ISOWEEKNUM(V19) -> 39 | X19: =+DAY(V19) -> 25 | Y19: Viernes | Z19: 5 | AA19: =+IF($I19=AA$7,1,0) -> 0 | AB19: =+IF($I19=AB$7,1,0) -> 1 | AC19: =+IF($I19=AC$7,1,0) -> 0 | AD19: =+IF($I19=AD$7,1,0) -> 0 | AE19: =+IF($I19=AE$7,1,0) -> 0
B20: =+T20&W20&H20 -> Sem3939ADOLFO DE JESUS LOPEZ CHAVEZ | C20: =+S20&T20 -> SEPTIEMBRESem39 | D20: =+S20&T20&H20 -> SEPTIEMBRESem39ADOLFO DE JESUS LOPEZ CHAVEZ | E20: =+S20&T20&W20&H20 -> SEPTIEMBRESem3939ADOLFO DE JESUS LOPEZ CHAVEZ | F20: =+H20&V20 -> ADOLFO DE JESUS LOPEZ CHAVEZ46291 | H20: ADOLFO DE JESUS LOPEZ CHAVEZ | I20: =+_xlfn.XLOOKUP($H20&$V20,BASEDATOS!$B:$B,BASEDATOS!F:F,0,0,1) -> DESCANSO | J20: =+_xlfn.XLOOKUP($H20&$V20,BASEDATOS!$B:$B,BASEDATOS!Q:Q,0,0,1) -> 0 | K20: =+_xlfn.XLOOKUP($H20&$V20,BASEDATOS!$B:$B,BASEDATOS!R:R,0,0,1) -> 0 | L20: =+IF(OR(J20="Descanso",J20="AUSENTE",J20="ASUETO"),0,MOD(K20-J20,1)) -> 0 | M20: =+IF(OR(I20="DIA",I20="NOCHE",I20="MIXTO"),"1:00",0) -> 0 | N20: =+IF(I20="ASUETO-D",8/24,IF(I20="ASUETO-N",6/24,MOD(L20-M20,1))) -> 0 | O20: =+O21 -> 0-5-2 | P20: =+IF(AND(Y20="Domingo",U20=7),_xlfn.XLOOKUP(O20,'Horarios y Sistemas'!C:C,'Horarios y Sistemas'!H:H,0,0,1),0) -> 0 | Q20: =IF(U20=U21,0,IF(AVERAGEIF(W:W,W20,U:U)=U20,0,_xlfn.XLOOKUP(O20,'Horarios y Sistemas'!C:C,'Horarios y Sistemas'!H:H,0,0,1)-P20))/7*U20 -> 0 | R20: =+IF(Y20="Domingo",SUM(P14:Q20),0) -> 0 | S20: =+UPPER(TEXT(V20,"MMMMMMMM")) -> SEPTIEMBRE | T20: =+"Sem"&W20 -> Sem39 | U20: =+COUNTIF(B:B,B20) -> 7 | V20: 46291 | W20: =+_xlfn.ISOWEEKNUM(V20) -> 39 | X20: =+DAY(V20) -> 26 | Y20: Sábado | Z20: 6 | AA20: =+IF($I20=AA$7,1,0) -> 0 | AB20: =+IF($I20=AB$7,1,0) -> 0 | AC20: =+IF($I20=AC$7,1,0) -> 1 | AD20: =+IF($I20=AD$7,1,0) -> 0 | AE20: =+IF($I20=AE$7,1,0) -> 0
